Workbook

Sheet Compare w prev (colored)
A3: Purpose | B3: Distance | D3: TSC | F3: TSC | H3: TSC | J3: TSC | L3: TSF | N3: TSF | P3: TSF | R3: Foundation | U3: Foundation | X3: Foundation | AA3: Foundation | AC3: TSF | AE3: TSF | AG3: TSF | AI3: TSF | AK3: Foundation | AN3: TSF | AP3: TSC | AR3: TSC
A4: Model | B4: DTW_D | D4: ROCKET | F4: HC2 | H4: Hydra | J4: MR+Hydra | L4: DLinear | N4: LightTS | P4: MTS-Mixer | R4: TimesNet | U4: ModernTCN | X4: TSLANet | AA4: TimeMixer++ | AC4: FEDformer | AE4: ETSformer | AG4: Crossformer | AI4: PatchTST | AK4: GPT4TS | AN4: iTransformer | AP4: InterpGN | AR4: TSCMamba
A5: Reference | B5: TimesNet | C5: ours | D5: TimesNet TSLANet TSCMamba | E5: ours | F5: original | G5: ours | H5: BORF | I5: ours | J5: BORF | K5: ours | L5: TimesNet TSLANet TSCMamba | M5: ours | N5: TimesNet | O5: ours | P5: ModernTCN | Q5: ours | R5: original | S5: TSLANet TSCMamba | T5: ours | U5: original | V5: revisited | W5: ours | X5: original | Y5: TSCMamba | Z5: ours | AA5: original | AB5: ours | AC5: TimesNet | AD5: ours | AE5: TimesNet | AF5: ours | AG5: ModernTCN TSLANet TSCMamba | AH5: ours | AI5: ModernTCN TSLANet TSCMamba | AJ5: ours | AK5: original | AL5: TSLANet TSCMamba | AM5: ours | AN5: TimeMixer++ | AO5: ours | AP5: original | AQ5: ours | AR5: original | AS5: ours
A6: EC | B6: 32.281369 | C6: 32.319392 | D6: 45.209125 | E6: 44.486692 | F6: 79.087452 | G6: 52.851711 | H6: 54.790875 | I6: 54.372624 | J6: 58.897338 | K6: 60.076046 | L6: 33.460076 | M6: 31.178707 | N6: 29.695817 | O6: 32.319392 | P6: 33.802281 | Q6: 30.798479 | R6: 35.703422 | S6: 27.718631 | T6: 33.460076 | U6: 36.311787 | V6: 31.901141 | W6: 32.319392 | X6: 30.418251 | Z6: 31.939163 | AA6: 39.885932 | AB6: 34.60076 | AC6: 31.21673 | AD6: 33.840304 | AE6: 28.098859 | AF6: 33.079848 | AG6: 37.984791 | AH6: 43.346008 | AI6: 32.813688 | AJ6: 32.69962 | AK6: 34.18251 | AL6: 25.475285 | AM6: 32.319392 | AN6: 28.098859 | AO6: 31.939163 | AP6: 30.418251 | AQ6: 28.897338 | AR6: 62.015209 | AS6: 30.798479
A7: FD | B7: 52.900114 | C7: 52.866061 | D7: 64.699205 | E7: 61.606129 | F7: 71.3479 | G7: 61.379115 | H7: 52.301362 | I7: 60.981839 | J7: 61.901249 | K7: 61.293984 | L7: 67.999432 | M7: 69.494892 | N7: 67.5 | O7: 68.473326 | P7: 70.198638 | Q7: 68.530079 | R7: 68.601022 | S7: 67.468785 | T7: 70.14756 | U7: 70.800227 | V7: 68.700341 | W7: 66.99773 | X7: 66.770715 | Z7: 66.969353 | AA7: 71.799092 | AB7: 69.665153 | AC7: 65.998865 | AD7: 69.892168 | AE7: 66.299659 | AF7: 68.331442 | AG7: 68.700341 | AH7: 69.636776 | AI7: 68.961407 | AJ7: 68.07605 | AK7: 69.199773 | AL7: 65.578888 | AM7: 68.61521 | AN7: 66.299659 | AO7: 68.416572 | AP7: 66.401816 | AQ7: 63.791146 | AR7: 69.401249 | AS7: 70.204313
A8: HW | B8: 28.6 | C8: 60.705882 | D8: 58.8 | E8: 59.294118 | F8: 56.341176 | G8: 56 | H8: 46.6 | I8: 56.352941 | J8: 51.4 | K8: 53.529412 | L8: 27 | M8: 23.764706 | N8: 26.105882 | O8: 25.058824 | P8: 26 | Q8: 19.647059 | R8: 32.105882 | S8: 26.176471 | T8: 37.529412 | U8: 30.6 | V8: 28.4 | W8: 30.117647 | X8: 57.882353 | Z8: 62 | AA8: 26.505882 | AB8: 33.647059 | AC8: 28 | AD8: 33.411765 | AE8: 32.505882 | AF8: 35.647059 | AG8: 28.8 | AH8: 30.352941 | AI8: 29.6 | AJ8: 29.529412 | AK8: 32.705882 | AL8: 3.7647059 | AM8: 34.117647 | AN8: 24.2 | AO8: 31.294118 | AP8: 61.882353 | AQ8: 58.705882 | AR8: 53.305882 | AS8: 45.058824
A9: HB | B9: 71.707317 | C9: 71.707317 | D9: 75.609756 | E9: 75.609756 | F9: 72.878049 | G9: 78.536585 | H9: 76.097561 | I9: 76.585366 | J9: 73.219512 | K9: 77.073171 | L9: 75.121951 | M9: 76.585366 | N9: 75.121951 | O9: 77.560976 | P9: 77.121951 | Q9: 79.02439 | R9: 78 | S9: 74.487805 | T9: 83.902439 | U9: 77.219512 | V9: 77.121951 | W9: 78.04878 | X9: 77.560976 | Z9: 79.512195 | AA9: 79.121951 | AB9: 80.487805 | AC9: 73.707317 | AD9: 78.04878 | AE9: 71.219512 | AF9: 78.536585 | AG9: 77.609756 | AH9: 79.02439 | AI9: 76.585366 | AJ9: 73.658537 | AK9: 77.219512 | AL9: 36.585366 | AM9: 79.02439 | AN9: 75.609756 | AO9: 78.04878 | AP9: 79.512195 | AQ9: 80.487805 | AR9: 76.585366 | AS9: 78.536585
A10: JV | B10: 94.891892 | C10: 95.945946 | D10: 96.189189 | E10: 83.783784 | G10: 98.378378 | H10: 97.810811 | I10: 97.837838 | J10: 97.810811 | K10: 98.378378 | L10: 97.837838 | M10: 96.486486 | N10: 96.189189 | O10: 96.756757 | P10: 94.297297 | Q10: 95.945946 | R10: 98.405405 | S10: 97.837838 | T10: 98.648649 | U10: 98.810811 | V10: 98.108108 | W10: 98.648649 | X10: 99.189189 | Z10: 98.918919 | AA10: 97.891892 | AB10: 99.189189 | AC10: 98.405405 | AD10: 97.567568 | AE10: 95.891892 | AF10: 98.378378 | AG10: 99.108108 | AH10: 98.378378 | AI10: 98.648649 | AJ10: 97.027027 | AK10: 98.594595 | AL10: 98.108108 | AM10: 98.108108 | AN10: 96.594595 | AO10: 98.108108 | AP10: 99.189189 | AQ10: 99.72973 | AR10: 97 | AS10: 98.378378
A11: PEMS | B11: 71.098266 | C11: 71.098266 | D11: 75.086705 | E11: 84.393064 | F11: 99.82659 | G11: 97.687861 | H11: 80.289017 | I11: 98.265896 | J11: 77.514451 | K11: 82.65896 | L11: 82.080925 | M11: 82.65896 | N11: 88.381503 | O11: 87.861272 | P11: 80.924855 | Q11: 82.080925 | R11: 89.595376 | S11: 88.150289 | T11: 87.861272 | U11: 89.075145 | V11: 83.179191 | W11: 86.705202 | X11: 83.815029 | Z11: 89.017341 | AA11: 90.982659 | AB11: 89.017341 | AC11: 80.924855 | AD11: 89.017341 | AE11: 86.011561 | AF11: 87.861272 | AG11: 85.895954 | AH11: 89.595376 | AI11: 89.306358 | AJ11: 89.017341 | AK11: 87.919075 | AL11: 87.283237 | AM11: 88.439306 | AN11: 87.919075 | AO11: 91.32948 | AP11: 88.439306 | AQ11: 86.127168 | AR11: 90.17341 | AS11: 90.17341
A12: SRS1 | B12: 77.713311 | C12: 77.474403 | D12: 90.784983 | E12: 85.665529 | F12: 87.883959 | G12: 89.078498 | H12: 86.68942 | I12: 86.68942 | J12: 95.187713 | K12: 94.880546 | L12: 88.395904 | M12: 92.832765 | N12: 89.795222 | O12: 92.832765 | P12: 91.706485 | Q12: 78.83959 | R12: 91.808874 | S12: 77.440273 | T12: 92.150171 | U12: 93.412969 | V12: 92.798635 | W12: 93.515358 | X12: 91.808874 | Z12: 89.761092 | AA12: 93.105802 | AB12: 92.150171 | AC12: 88.703072 | AD12: 75.085324 | AE12: 89.590444 | AF12: 92.150171 | AG12: 92.491468 | AH12: 93.856655 | AI12: 90.716724 | AJ12: 89.078498 | AK12: 93.208191 | AL12: 91.467577 | AM12: 93.174061 | AN12: 90.204778 | AO12: 93.856655 | AP12: 92.491468 | AQ12: 90.443686 | AR12: 92.491468 | AS12: 92.832765
A13: SRS2 | B13: 53.888889 | C13: 53.888889 | D13: 54.444444 | E13: 55.555556 | F13: 50.444444 | G13: 54.444444 | H13: 58.888889 | I13: 58.888889 | J13: 56.722222 | K13: 55 | L13: 51.666667 | M13: 57.222222 | N13: 51.111111 | O13: 59.444444 | P13: 55 | Q13: 58.333333 | R13: 57.222222 | S13: 52.833333 | T13: 60 | U13: 60.277778 | V13: 61.722222 | W13: 60 | X13: 61.666667 | Z13: 63.888889 | AA13: 65.611111 | AB13: 60.555556 | AC13: 54.388889 | AD13: 59.444444 | AE13: 55 | AF13: 60 | AG13: 58.277778 | AH13: 61.666667 | AI13: 57.777778 | AJ13: 61.666667 | AK13: 59.388889 | AL13: 51.666667 | AM13: 60.555556 | AN13: 54.388889 | AO13: 58.888889 | AP13: 57.777778 | AQ13: 58.333333 | AR13: 66.722222 | AS13: 62.222222
A14: SAD | B14: 96.298317 | C14: 97.226012 | D14: 99.199636 | E14: 99.226921 | G14: 99.135971 | H14: 98.8995 | I14: 99.135971 | J14: 99.299682 | K14: 99.04502 | L14: 96.680309 | M14: 96.953161 | N14: 100 | O14: 98.226467 | P14: 97.398818 | Q14: 99.454297 | R14: 98.999545 | S14: 98.358345 | T14: 99.545248 | U14: 98.699409 | V14: 98.099136 | W14: 99.499773 | X14: 99.90905 | Z14: 98.044566 | AA14: 99.799909 | AB14: 99.545248 | AC14: 100 | AD14: 99.454297 | AE14: 100 | AF14: 98.999545 | AG14: 97.899045 | AH14: 98.86312 | AI14: 99.681673 | AJ14: 98.817644 | AK14: 99.199636 | AL14: 99.363347 | AM14: 99.590723 | AN14: 95.998181 | AO14: 99.317872 | AP14: 99.818099 | AQ14: 99.863574 | AR14: 98.999545 | AS14: 95.81628
A15: UW | B15: 90.3125 | C15: 90.3125 | D15: 94.40625 | E15: 94.0625 | F15: 94.875 | G15: 94.0625 | H15: 90.90625 | I15: 94.375 | J15: 94.09375 | K15: 94.0625 | L15: 82.09375 | M15: 82.8125 | N15: 80.3125 | O15: 89.0625 | P15: 82.3125 | Q15: 83.125 | R15: 85.3125 | S15: 83.125 | T15: 88.4375 | U15: 86.6875 | V15: 85.90625 | W15: 88.4375 | X15: 91.25 | Z15: 94.375 | AA15: 88.1875 | AB15: 90.625 | AC15: 85.3125 | AD15: 79.6875 | AE15: 85 | AF15: 89.6875 | AG15: 85.3125 | AH15: 88.4375 | AI15: 85.8125 | AJ15: 89.375 | AK15: 88.09375 | AL15: 84.375 | AM15: 89.0625 | AN15: 85.90625 | AO15: 90 | AP15: 91.875 | AQ15: 88.4375 | AR15: 93.8125 | AS15: 95.3125
A16: AWR | C16: 98.666667 | D16: 99.333333 | E16: 99.333333 | F16: 99.566667 | G16: 99.333333 | H16: 99 | I16: 99.333333 | J16: 99.333333 | K16: 99.333333 | L16: 97.333333 | M16: 97.666667 | O16: 98.333333 | Q16: 99 | S16: 96.166667 | T16: 98.666667 | W16: 98.666667 | X16: 99 | Z16: 99.333333 | AB16: 99 | AD16: 92.333333 | AF16: 98.666667 | AG16: 98 | AH16: 98.666667 | AI16: 97.666667 | AJ16: 98.666667 | AL16: 93.333333 | AM16: 98.666667 | AO16: 99 | AP16: 99.666667 | AQ16: 99 | AR16: 97 | AS16: 99.333333
A17: AF | C17: 20 | D17: 20 | E17: 6.6666667 | F17: 28 | G17: 20 | H17: 13.333333 | I17: 26.666667 | J17: 6.6666667 | K17: 6.6666667 | L17: 46.666667 | M17: 53.333333 | O17: 73.333333 | Q17: 60 | S17: 33.333333 | T17: 66.666667 | W17: 73.333333 | X17: 40 | Z17: 66.666667 | AB17: 66.666667 | AD17: 73.333333 | AF17: 80 | AG17: 46.666667 | AH17: 73.333333 | AI17: 53.333333 | AJ17: 80 | AL17: 33.333333 | AM17: 66.666667 | AO17: 66.666667 | AP17: 33.333333 | AQ17: 46.666667 | AR17: 67.333333 | AS17: 66.666667
A18: BM | C18: 97.5 | D18: 100 | E18: 100 | F18: 99 | G18: 100 | H18: 100 | I18: 100 | J18: 100 | K18: 100 | L18: 85 | M18: 87.5 | O18: 100 | Q18: 100 | S18: 100 | T18: 100 | W18: 100 | X18: 100 | Z18: 100 | AB18: 100 | AD18: 95 | AF18: 100 | AG18: 90 | AH18: 100 | AI18: 92.5 | AJ18: 85 | AL18: 92.5 | AM18: 100 | AO18: 97.5 | AP18: 100 | AQ18: 100 | AR18: 100 | AS18: 100
A19: CT | C19: 98.816156 | D19: 98.753482 | E19: 99.303621 | G19: 99.303621 | H19: 98.600279 | I19: 99.164345 | J19: 99.199164 | K19: 99.373259 | L19: 97.346797 | M19: 98.119777 | O19: 98.955432 | Q19: 97.980501 | S19: 97.980501 | T19: 98.746518 | W19: 99.303621 | Y19: 98.746518 | Z19: 99.164345 | AB19: 99.373259 | AD19: 97.284123 | AF19: 98.467967 | AG19: 98.328691 | AH19: 98.955432 | AI19: 97.346797 | AJ19: 98.398329 | AL19: 98.259053 | AM19: 99.373259 | AO19: 98.885794 | AP19: 99.791086 | AQ19: 99.791086 | AR19: 98.997214 | AS19: 99.512535
A20: CR | C20: 100 | D20: 98.611111 | E20: 100 | F20: 100 | G20: 100 | H20: 98.611111 | I20: 100 | J20: 98.611111 | K20: 98.611111 | L20: 91.666667 | M20: 91.666667 | O20: 93.055556 | Q20: 97.222222 | S20: 87.5 | T20: 97.222222 | W20: 97.222222 | X20: 98.611111 | Z20: 91.666667 | AB20: 98.611111 | AD20: 90.277778 | AF20: 98.611111 | AG20: 84.722222 | AH20: 97.222222 | AI20: 84.722222 | AJ20: 97.222222 | AL20: 8.3333333 | AM20: 97.222222 | AO20: 97.222222 | AP20: 100 | AQ20: 100 | AR20: 98.611111 | AS20: 100
A21: DDG | C21: 58 | D21: 52 | E21: 52 | F21: 49.8 | G21: 70 | H21: 68 | I21: 68 | J21: 64 | K21: 60 | L21: 62 | M21: 66 | O21: 56 | Q21: 68 | S21: 56 | T21: 68 | W21: 66 | Y21: 24 | Z21: 74 | AB21: 74 | AD21: 42 | AF21: 42 | AG21: 44 | AH21: 72 | AI21: 24 | AJ21: 40 | AL21: 50 | AM21: 66 | AO21: 60 | AP21: 68 | AQ21: 76 | AR21: 62 | AS21: 50
A22: EW | C22: 61.832061 | D22: 78.625954 | E22: 91.603053 | F22: 89.465649 | G22: 97.709924 | H22: 98.473282 | I22: 98.473282 | J22: 96.183206 | K22: 98.473282 | L22: 41.221374 | M22: 42.748092 | O22: 54.198473 | Q22: 66.412214 | S22: 58.778626 | T22: 63.358779 | W22: 64.122137 | Y22: 41.221374 | Z22: 81.679389 | AB22: 61.068702 | AD22: 63.358779 | AF22: 70.992366 | AG22: 54.961832 | AH22: 58.015267 | AI22: 54.198473 | AJ22: 57.251908 | AL22: 48.091603 | AM22: 66.412214 | AO22: 59.541985 | AP22: 83.969466 | AQ22: 82.442748 | AR22: 87.022901 | AS22: 88.549618
A23: EP | C23: 96.376812 | D23: 98.550725 | E23: 99.275362 | F23: 99.782609 | G23: 100 | H23: 100 | I23: 100 | J23: 100 | K23: 100 | L23: 60.144928 | M23: 65.217391 | O23: 97.101449 | Q23: 66.666667 | S23: 78.115942 | T23: 96.376812 | W23: 96.376812 | X23: 98.550725 | Z23: 100 | AB23: 94.927536 | AD23: 92.753623 | AF23: 92.753623 | AG23: 73.188406 | AH23: 95.652174 | AI23: 65.942029 | AJ23: 98.550725 | AL23: 85.507246 | AM23: 89.855072 | AO23: 80.434783 | AP23: 99.275362 | AQ23: 97.826087 | AR23: 97.101449 | AS23: 99.275362
A24: ER | C24: 91.481481 | D24: 94.074074 | E24: 98.888889 | F24: 98.518519 | G24: 98.888889 | H24: 98.518519 | I24: 98.888889 | J24: 98.888889 | K24: 99.259259 | L24: 91.481481 | M24: 91.851852 | O24: 94.444444 | Q24: 77.777778 | S24: 94.074074 | T24: 95.555556 | W24: 97.407407 | Y24: 91.481481 | Z24: 85.925926 | AB24: 96.296296 | AD24: 95.925926 | AF24: 96.296296 | AG24: 94.074074 | AH24: 97.407407 | AI24: 92.592593 | AJ24: 96.666667 | AL24: 95.925926 | AM24: 96.296296 | AO24: 94.814815 | AP24: 95.185185 | AQ24: 87.777778 | AR24: 91.518519 | AS24: 97.037037
A25: FM | C25: 53 | D25: 61 | E25: 57 | F25: 55.2 | G25: 61 | H25: 55 | I25: 55 | J25: 56 | K25: 60 | L25: 64 | M25: 62 | O25: 64 | Q25: 63 | S25: 59.4 | T25: 66 | W25: 67 | X25: 61 | Z25: 68 | AB25: 67 | AD25: 72 | AF25: 66 | AG25: 64 | AH25: 64 | AI25: 62 | AJ25: 63 | AL25: 57 | AM25: 66 | AO25: 64 | AP25: 64 | AQ25: 67 | AR25: 69 | AS25: 66
A26: HMD | C26: 18.918919 | D26: 50 | E26: 51.351351 | F26: 39.72973 | G26: 48.648649 | H26: 21.621622 | I26: 51.351351 | J26: 36.486486 | K26: 36.486486 | L26: 58.108108 | M26: 66.216216 | O26: 66.216216 | Q26: 70.27027 | S26: 50 | T26: 72.972973 | W26: 66.216216 | X26: 52.702703 | Z26: 48.648649 | AB26: 72.972973 | AD26: 71.621622 | AF26: 63.513514 | AG26: 58.108108 | AH26: 66.216216 | AI26: 58.108108 | AJ26: 63.513514 | AL26: 18.918919 | AM26: 70.27027 | AO26: 58.108108 | AP26: 48.648649 | AQ26: 45.945946 | AR26: 71.621622 | AS26: 60.810811
A27: IW | C27: 48.692 | D27: 10 | E27: 38.524 | G27: 66.796 | H27: 67.9 | I27: 67.052 | J27: 66.7 | K27: 65.744 | L27: 10 | M27: 18.996 | O27: 71.676 | Q27: 72.424 | S27: 10 | T27: 64.024 | W27: 75.588 | X27: 10 | Z27: 10.012 | AB27: 64.192 | AD27: 65.244 | AF27: 64.868 | AG27: 10 | AH27: 73.712 | AI27: 10 | AJ27: 60.936 | AL27: 10 | AM27: 61.396 | AO27: 73.436 | AP27: 66.752 | AQ27: 67.18 | AR27: 14.3 | AS27: 68.244
A28: LIB | C28: 87.222222 | D28: 83.888889 | E28: 90.555556 | F28: 92.666667 | G28: 94.444444 | H28: 93.277778 | I28: 93.333333 | J28: 92.777778 | K28: 93.333333 | L28: 73.333333 | M28: 70.555556 | O28: 89.444444 | Q28: 34.444444 | S28: 77.833333 | T28: 88.333333 | W28: 90 | X28: 92.777778 | Z28: 95.555556 | AB28: 88.333333 | AD28: 93.333333 | AF28: 90 | AG28: 76.111111 | AH28: 90.555556 | AI28: 81.111111 | AJ28: 81.666667 | AL28: 79.444444 | AM28: 87.777778 | AO28: 91.666667 | AP28: 97.222222 | AQ28: 97.222222 | AR28: 90 | AS28: 91.666667
A29: LSST | C29: 55.109489 | D29: 54.099757 | E29: 64.030819 | F29: 63.694242 | G29: 66.382806 | H29: 60.701541 | I29: 66.504461 | J29: 63.600973 | K29: 64.274128 | L29: 35.770479 | M29: 34.022709 | O29: 41.524736 | Q29: 34.184915 | S29: 59.209246 | T29: 44.120032 | W29: 43.592863 | X29: 66.3382 | Z29: 51.013788 | AB29: 44.444444 | AD29: 40.997567 | AF29: 41.240876 | AG29: 42.818329 | AH29: 41.768045 | AI29: 67.798054 | AJ29: 56.731549 | AL29: 46.390916 | AM29: 38.077859 | AO29: 40.673155 | AP29: 60.665045 | AQ29: 59.570154 | AR29: 60.300081 | AS29: 60.056772
A30: MI | C30: 50 | D30: 53 | E30: 54 | F30: 53.2 | G30: 50 | H30: 50 | I30: 54 | J30: 48 | K30: 51 | L30: 61 | M30: 64 | O30: 68 | Q30: 66 | S30: 51 | T30: 68 | W30: 67 | X30: 62 | Z30: 71 | AB30: 67 | AD30: 65 | AF30: 67 | AG30: 61 | AH30: 68 | AI30: 61 | AJ30: 69 | AL30: 50 | AM30: 67 | AO30: 67 | AP30: 64 | AQ30: 67 | AR30: 62 | AS30: 67
A31: NATO | C31: 88.333333 | D31: 83.333333 | E31: 89.444444 | F31: 89.222222 | G31: 91.111111 | H31: 87.222222 | I31: 90 | J31: 91.722222 | K31: 93.333333 | L31: 93.888889 | M31: 96.111111 | O31: 97.222222 | Q31: 95 | S31: 81.833333 | T31: 98.333333 | W31: 95.555556 | X31: 95.555556 | Z31: 99.444444 | AB31: 96.111111 | AD31: 96.111111 | AF31: 93.333333 | AG31: 88.333333 | AH31: 93.888889 | AI31: 96.666667 | AJ31: 80.555556 | AL31: 91.666667 | AM31: 96.111111 | AO31: 88.888889 | AP31: 98.888889 | AQ31: 98.888889 | AR31: 94.444444 | AS31: 92.222222
A32: PD | C32: 97.712979 | D32: 97.341338 | E32: 98.227559 | F32: 99.55689 | G32: 97.655803 | H32: 96.801029 | I32: 97.855918 | J32: 96.801029 | K32: 97.284162 | L32: 92.938822 | M32: 92.481418 | O32: 96.998285 | Q32: 46.941109 | S32: 98.190395 | T32: 98.913665 | W32: 98.513436 | X32: 98.939394 | Z32: 99.028016 | AB32: 98.5992 | AD32: 98.5992 | AF32: 98.542024 | AG32: 93.650658 | AH32: 98.513436 | AI32: 99.230989 | AJ32: 98.484848 | AL32: 97.741567 | AM32: 98.513436 | AO32: 98.427673 | AP32: 99.142367 | AQ32: 99.342481 | AR32: 98.542024 | AS32: 98.513436
A33: PS | C33: 15.120787 | D33: 17.599165 | E33: 27.825828 | F33: 29.427378 | G33: 33.01521 | H33: 32.400835 | I33: 33.16433 | J33: 35.401133 | K33: 33.641515 | L33: 7.1011035 | M33: 6.6507605 | O33: 16.224277 | Q33: 5.4279749 | S33: 18.240382 | T33: 14.524307 | W33: 13.748882 | X33: 17.751268 | Z33: 4.9209663 | AB33: 15.5085 | AD33: 11.691023 | AF33: 14.315538 | AG33: 7.5514465 | AH33: 14.25589 | AI33: 11.691023 | AJ33: 15.090963 | AL33: 3.0122279 | AM33: 13.122577 | AO33: 11.541903 | AP33: 32.180137 | AQ33: 33.074858 | AR33: 24.658515 | AS33: 23.799582
A34: RS | C34: 80.263158 | D34: 86.184211 | E34: 90.789474 | F34: 93.026316 | G34: 90.131579 | H34: 91.381579 | I34: 91.447368 | J34: 90.789474 | K34: 90.131579 | L34: 78.947368 | M34: 78.947368 | O34: 81.578947 | Q34: 86.842105 | S34: 82.631579 | T34: 89.473684 | W34: 84.210526 | X34: 90.789474 | Z34: 94.078947 | AB34: 91.447368 | AD34: 84.868421 | AF34: 85.526316 | AG34: 81.578947 | AH34: 87.5 | AI34: 84.210526 | AJ34: 85.526316 | AL34: 76.973684 | AM34: 86.842105 | AO34: 81.578947 | AP34: 90.789474 | AQ34: 91.447368 | AR34: 91.447368 | AS34: 90.789474
A35: SWJ | C35: 20 | D35: 46.666667 | E35: 46.666667 | F35: 44 | G35: 40 | H35: 40 | I35: 40 | J35: 60 | K35: 66.666667 | L35: 60 | M35: 53.333333 | O35: 73.333333 | Q35: 66.666667 | S35: 53.333333 | T35: 66.666667 | W35: 80 | X35: 46.666667 | Z35: 73.333333 | AB35: 73.333333 | AD35: 66.666667 | AF35: 66.666667 | AG35: 53.333333 | AH35: 80 | AI35: 60 | AJ35: 86.666667 | AL35: 33.333333 | AM35: 73.333333 | AO35: 73.333333 | AP35: 53.333333 | AQ35: 60 | AR35: 73.333333 | AS35: 73.333333
A36: report <= ours | B36: {=SUM(--(B6:B35<=C6:C35))-COUNTBLANK(B6:B35)} -> 8 | D36: {=SUM(--(D6:D35<=E6:E35))-COUNTBLANK(D6:D35)} -> 23 | F36: {=SUM(--(F6:F35<=G6:G35))-COUNTBLANK(F6:F35)} -> 15 | H36: {=SUM(--(H6:H35<=I6:I35))-COUNTBLANK(H6:H35)} -> 28 | J36: {=SUM(--(J6:J35<=K6:K35))-COUNTBLANK(J6:J35)} -> 21 | L36: {=SUM(--(L6:L35<=M6:M35))-COUNTBLANK(L6:L35)} -> 21 | N36: {=SUM(--(N6:N35<=O6:O35))-COUNTBLANK(N6:N35)} -> 7 | P36: {=SUM(--(P6:P35<=Q6:Q35))-COUNTBLANK(P6:P35)} -> 6 | R36: {=SUM(--(R6:R35<=T6:T35))-COUNTBLANK(R6:R35)} -> 8 | S36: {=SUM(--(S6:S35<=T6:T35))-COUNTBLANK(S6:S35)} -> 27 | U36: {=SUM(--(U6:U35<=W6:W35))-COUNTBLANK(U6:U35)} -> 4 | V36: {=SUM(--(V6:V35<=W6:W35))-COUNTBLANK(V6:V35)} -> 8 | X36: {=SUM(--(X6:X35<=Z6:Z35))-COUNTBLANK(X6:X35)} -> 19 | Y36: {=SUM(--(Y6:Y35<=Z6:Z35))-COUNTBLANK(Y6:Y35)} -> 3 | AA36: {=SUM(--(AA6:AA35<=AB6:AB35))-COUNTBLANK(AA6:AA35)} -> 4 | AC36: {=SUM(--(AC6:AC35<=AD6:AD35))-COUNTBLANK(AC6:AC35)} -> 6 | AE36: {=SUM(--(AE6:AE35<=AF6:AF35))-COUNTBLANK(AE6:AE35)} -> 9 | AG36: {=SUM(--(AG6:AG35<=AH6:AH35))-COUNTBLANK(AG6:AG35)} -> 28 | AI36: {=SUM(--(AI6:AI35<=AJ6:AJ35))-COUNTBLANK(AI6:AI35)} -> 18 | AK36: {=SUM(--(AK6:AK35<=AM6:AM35))-COUNTBLANK(AK6:AK35)} -> 6 | AL36: {=SUM(--(AL6:AL35<=AM6:AM35))-COUNTBLANK(AL6:AL35)} -> 29 | AN36: {=SUM(--(AN6:AN35<=AO6:AO35))-COUNTBLANK(AN6:AN35)} -> 10 | AP36: {=SUM(--(AP6:AP35<=AQ6:AQ35))-COUNTBLANK(AP6:AP35)} -> 18 | AR36: {=SUM(--(AR6:AR35<=AS6:AS35))} -> 17
A37: report >= ours | B37: {=SUM(--(B6:B35>=C6:C35))} -> 6 | D37: {=SUM(--(D6:D35>=E6:E35))} -> 12 | F37: {=SUM(--(F6:F35>=G6:G35))} -> 12 | H37: {=SUM(--(H6:H35>=I6:I35))} -> 10 | J37: {=SUM(--(J6:J35>=K6:K35))} -> 15 | L37: {=SUM(--(L6:L35>=M6:M35))} -> 11 | N37: {=SUM(--(N6:N35>=O6:O35))} -> 3 | P37: {=SUM(--(P6:P35>=Q6:Q35))} -> 4 | R37: {=SUM(--(R6:R35>=T6:T35))} -> 2 | S37: {=SUM(--(S6:S35>=T6:T35))} -> 4 | U37: {=SUM(--(U6:U35>=W6:W35))} -> 6 | V37: {=SUM(--(V6:V35>=W6:W35))} -> 2 | X37: {=SUM(--(X6:X35>=Z6:Z35))} -> 8 | Y37: {=SUM(--(Y6:Y35>=Z6:Z35))} -> 1 | AA37: {=SUM(--(AA6:AA35>=AB6:AB35))} -> 6 | AC37: {=SUM(--(AC6:AC35>=AD6:AD35))} -> 4 | AE37: {=SUM(--(AE6:AE35>=AF6:AF35))} -> 1 | AG37: {=SUM(--(AG6:AG35>=AH6:AH35))} -> 3 | AI37: {=SUM(--(AI6:AI35>=AJ6:AJ35))} -> 12 | AK37: {=SUM(--(AK6:AK35>=AM6:AM35))} -> 4 | AL37: {=SUM(--(AL6:AL35>=AM6:AM35))} -> 2 | AN37: {=SUM(--(AN6:AN35>=AO6:AO35))} -> 0 | AP37: {=SUM(--(AP6:AP35>=AQ6:AQ35))} -> 17 | AR37: {=SUM(--(AR6:AR35>=AS6:AS35))-COUNTBLANK(AS6:AS35)} -> 16
A38: acc. difference | B38: =B74 -> 3.3852694 | D38: =D74 -> 2.0559779 | F38: =F74 -> 0.22388484 | H38: =H74 -> 3.3201416 | J38: =J74 -> 0.74673128 | L38: =L74 -> 1.2373938 | N38: =N74 -> 2.3383544 | P38: =P74 -> -1.2983726 | R38: =R74 -> 1.5928077 | S38: =S74 -> 9.0140008 | U38: =U74 -> -0.76051065 | V38: =V74 -> 0.83530567 | X38: =X74 -> 2.1605734 | Y38: =Y74 -> 21.330072 | AA38: =AA74 -> -0.34084485 | AC38: =AC74 -> 0.87918586 | AE38: =AE74 -> 3.305399 | AG38: =AG74 -> 9.0104483 | AI38: =AI74 -> 5.2617219 | AK38: =AK74 -> 0.32950804 | AL38: =AL74 -> 15.617 | AN38: =AN74 -> 3.5979595 | AP38: =AP74 -> 0.27815927 | AR38: =AR74 -> 0.080194679
B41: =B4 -> DTW_D | D41: =D4 -> ROCKET | F41: =F4 -> HC2 | H41: =H4 -> Hydra | J41: =J4 -> MR+Hydra | L41: =L4 -> DLinear | N41: =N4 -> LightTS | P41: =P4 -> MTS-Mixer | R41: =R4 -> TimesNet | S41: =S4 -> 0 | U41: =U4 -> ModernTCN | V41: =V4 -> 0 | X41: =X4 -> TSLANet | Y41: =Y4 -> 0 | AA41: =AA4 -> TimeMixer++ | AC41: =AC4 -> FEDformer | AE41: =AE4 -> ETSformer | AG41: =AG4 -> Crossformer | AI41: =AI4 -> PatchTST | AK41: =AK4 -> GPT4TS | AL41: =AL4 -> 0 | AN41: =AN4 -> iTransformer | AP41: =AP4 -> InterpGN | AR41: =AR4 -> TSCMamba
B42: =B6-C6 -> -0.038022814 | D42: =D6-E6 -> 0.72243346 | F42: =F6-G6 -> 26.235741 | H42: =H6-I6 -> 0.41825095 | J42: =J6-K6 -> -1.1787072 | L42: =L6-M6 -> 2.2813688 | N42: =N6-O6 -> -2.6235741 | P42: =P6-Q6 -> 3.0038023 | R42: =R6-T6 -> 2.243346 | S42: =S6-T6 -> -5.7414449 | U42: =U6-W6 -> 3.9923954 | V42: =V6-W6 -> -0.41825095 | X42: =X6-Z6 -> -1.5209125 | AA42: =AA6-AB6 -> 5.2851711 | AC42: =AC6-AD6 -> -2.6235741 | AE42: =AE6-AF6 -> -4.9809886 | AG42: =AG6-AH6 -> -5.3612167 | AI42: =AI6-AJ6 -> 0.11406844 | AK42: =AK6-AM6 -> 1.8631179 | AL42: =AL6-AM6 -> -6.8441065 | AN42: =AN6-AO6 -> -3.8403042 | AP42: =AP6-AQ6 -> 1.5209125 | AR42: =AR6-AS6 -> 31.21673
B43: =B7-C7 -> 0.034052213 | D43: =D7-E7 -> 3.093076 | F43: =F7-G7 -> 9.9687855 | H43: =H7-I7 -> -8.6804767 | J43: =J7-K7 -> 0.60726447 | L43: =L7-M7 -> -1.4954597 | N43: =N7-O7 -> -0.97332577 | P43: =P7-Q7 -> 1.6685585 | R43: =R7-T7 -> -1.546538 | S43: =S7-T7 -> -2.6787741 | U43: =U7-W7 -> 3.8024972 | V43: =V7-W7 -> 1.7026107 | X43: =X7-Z7 -> -0.19863791 | AA43: =AA7-AB7 -> 2.1339387 | AC43: =AC7-AD7 -> -3.8933031 | AE43: =AE7-AF7 -> -2.0317821 | AG43: =AG7-AH7 -> -0.93643587 | AI43: =AI7-AJ7 -> 0.88535755 | AK43: =AK7-AM7 -> 0.584563 | AL43: =AL7-AM7 -> -3.0363224 | AN43: =AN7-AO7 -> -2.1169126 | AP43: =AP7-AQ7 -> 2.6106697 | AR43: =AR7-AS7 -> -0.8030647
B44: =B8-C8 -> -32.105882 | D44: =D8-E8 -> -0.49411765 | F44: =F8-G8 -> 0.34117647 | H44: =H8-I8 -> -9.7529412 | J44: =J8-K8 -> -2.1294118 | L44: =L8-M8 -> 3.2352941 | N44: =N8-O8 -> 1.0470588 | P44: =P8-Q8 -> 6.3529412 | R44: =R8-T8 -> -5.4235294 | S44: =S8-T8 -> -11.352941 | U44: =U8-W8 -> 0.48235294 | V44: =V8-W8 -> -1.7176471 | X44: =X8-Z8 -> -4.1176471 | AA44: =AA8-AB8 -> -7.1411765 | AC44: =AC8-AD8 -> -5.4117647 | AE44: =AE8-AF8 -> -3.1411765 | AG44: =AG8-AH8 -> -1.5529412 | AI44: =AI8-AJ8 -> 0.070588235 | AK44: =AK8-AM8 -> -1.4117647 | AL44: =AL8-AM8 -> -30.352941 | AN44: =AN8-AO8 -> -7.0941176 | AP44: =AP8-AQ8 -> 3.1764706 | AR44: =AR8-AS8 -> 8.2470588
...

Sheet Compare w prev
A3: Purpose | B3: Distance | D3: TSC | F3: TSC | H3: TSC | J3: TSC | L3: TSF | N3: TSF | P3: TSF | R3: Foundation | U3: Foundation | X3: Foundation | AA3: Foundation | AC3: TSF | AE3: TSF | AG3: TSF | AI3: TSF | AK3: Foundation | AN3: TSF | AP3: TSC | AR3: TSC
A4: Model | B4: DTW_D | D4: ROCKET | F4: HC2 | H4: Hydra | J4: MR+Hydra | L4: DLinear | N4: LightTS | P4: MTS-Mixer | R4: TimesNet | U4: ModernTCN | X4: TSLANet | AA4: TimeMixer++ | AC4: FEDformer | AE4: ETSformer | AG4: Crossformer | AI4: PatchTST | AK4: GPT4TS | AN4: iTransformer | AP4: InterpGN | AR4: TSCMamba
A5: Reference | B5: TimesNet | C5: ours | D5: TimesNet TSLANet TSCMamba | E5: ours | F5: original | G5: ours | H5: BORF | I5: ours | J5: BORF | K5: ours | L5: TimesNet TSLANet TSCMamba | M5: ours | N5: TimesNet | O5: ours | P5: ModernTCN | Q5: ours | R5: original | S5: TSLANet TSCMamba | T5: ours | U5: original | V5: revisited | W5: ours | X5: original | Y5: TSCMamba | Z5: ours | AA5: original | AB5: ours | AC5: TimesNet | AD5: ours | AE5: TimesNet | AF5: ours | AG5: ModernTCN TSLANet TSCMamba | AH5: ours | AI5: ModernTCN TSLANet TSCMamba | AJ5: ours | AK5: original | AL5: TSLANet TSCMamba | AM5: ours | AN5: TimeMixer++ | AO5: ours | AP5: original | AQ5: ours | AR5: original | AS5: ours
A6: EC | B6: ='Compare w prev (colored)'!B6 -> 32.281369 | C6: ='Compare w prev (colored)'!C6 -> 32.319392 | D6: ='Compare w prev (colored)'!D6 -> 45.209125 | E6: ='Compare w prev (colored)'!E6 -> 44.486692 | F6: ='Compare w prev (colored)'!F6 -> 79.087452 | G6: ='Compare w prev (colored)'!G6 -> 52.851711 | H6: ='Compare w prev (colored)'!H6 -> 54.790875 | I6: ='Compare w prev (colored)'!I6 -> 54.372624 | ... X6: ='Compare w prev (colored)'!X6 -> 30.418251 | Z6: ='Compare w prev (colored)'!Z6 -> 31.939163 | AA6: ='Compare w prev (colored)'!AA6 -> 39.885932 | AB6: ='Compare w prev (colored)'!AB6 -> 34.60076 | AC6: ='Compare w prev (colored)'!AC6 -> 31.21673 | AD6: ='Compare w prev (colored)'!AD6 -> 33.840304 | AE6: ='Compare w prev (colored)'!AE6 -> 28.098859 | AF6: ='Compare w prev (colored)'!AF6 -> 33.079848 | AG6: ='Compare w prev (colored)'!AG6 -> 37.984791 | ... AS6: ='Compare w prev (colored)'!AS6 -> 30.798479
A7: FD | B7: ='Compare w prev (colored)'!B7 -> 52.900114 | C7: ='Compare w prev (colored)'!C7 -> 52.866061 | D7: ='Compare w prev (colored)'!D7 -> 64.699205 | E7: ='Compare w prev (colored)'!E7 -> 61.606129 | F7: ='Compare w prev (colored)'!F7 -> 71.3479 | G7: ='Compare w prev (colored)'!G7 -> 61.379115 | H7: ='Compare w prev (colored)'!H7 -> 52.301362 | I7: ='Compare w prev (colored)'!I7 -> 60.981839 | ... X7: ='Compare w prev (colored)'!X7 -> 66.770715 | Z7: ='Compare w prev (colored)'!Z7 -> 66.969353 | AA7: ='Compare w prev (colored)'!AA7 -> 71.799092 | AB7: ='Compare w prev (colored)'!AB7 -> 69.665153 | AC7: ='Compare w prev (colored)'!AC7 -> 65.998865 | AD7: ='Compare w prev (colored)'!AD7 -> 69.892168 | AE7: ='Compare w prev (colored)'!AE7 -> 66.299659 | AF7: ='Compare w prev (colored)'!AF7 -> 68.331442 | AG7: ='Compare w prev (colored)'!AG7 -> 68.700341 | ... AS7: ='Compare w prev (colored)'!AS7 -> 70.204313
A8: HW | B8: ='Compare w prev (colored)'!B8 -> 28.6 | C8: ='Compare w prev (colored)'!C8 -> 60.705882 | D8: ='Compare w prev (colored)'!D8 -> 58.8 | E8: ='Compare w prev (colored)'!E8 -> 59.294118 | F8: ='Compare w prev (colored)'!F8 -> 56.341176 | G8: ='Compare w prev (colored)'!G8 -> 56 | H8: ='Compare w prev (colored)'!H8 -> 46.6 | I8: ='Compare w prev (colored)'!I8 -> 56.352941 | ... X8: ='Compare w prev (colored)'!X8 -> 57.882353 | Z8: ='Compare w prev (colored)'!Z8 -> 62 | AA8: ='Compare w prev (colored)'!AA8 -> 26.505882 | AB8: ='Compare w prev (colored)'!AB8 -> 33.647059 | AC8: ='Compare w prev (colored)'!AC8 -> 28 | AD8: ='Compare w prev (colored)'!AD8 -> 33.411765 | AE8: ='Compare w prev (colored)'!AE8 -> 32.505882 | AF8: ='Compare w prev (colored)'!AF8 -> 35.647059 | AG8: ='Compare w prev (colored)'!AG8 -> 28.8 | ... AS8: ='Compare w prev (colored)'!AS8 -> 45.058824
A9: HB | B9: ='Compare w prev (colored)'!B9 -> 71.707317 | C9: ='Compare w prev (colored)'!C9 -> 71.707317 | D9: ='Compare w prev (colored)'!D9 -> 75.609756 | E9: ='Compare w prev (colored)'!E9 -> 75.609756 | F9: ='Compare w prev (colored)'!F9 -> 72.878049 | G9: ='Compare w prev (colored)'!G9 -> 78.536585 | H9: ='Compare w prev (colored)'!H9 -> 76.097561 | I9: ='Compare w prev (colored)'!I9 -> 76.585366 | ... X9: ='Compare w prev (colored)'!X9 -> 77.560976 | Z9: ='Compare w prev (colored)'!Z9 -> 79.512195 | AA9: ='Compare w prev (colored)'!AA9 -> 79.121951 | AB9: ='Compare w prev (colored)'!AB9 -> 80.487805 | AC9: ='Compare w prev (colored)'!AC9 -> 73.707317 | AD9: ='Compare w prev (colored)'!AD9 -> 78.04878 | AE9: ='Compare w prev (colored)'!AE9 -> 71.219512 | AF9: ='Compare w prev (colored)'!AF9 -> 78.536585 | AG9: ='Compare w prev (colored)'!AG9 -> 77.609756 | ... AS9: ='Compare w prev (colored)'!AS9 -> 78.536585
A10: JV | B10: ='Compare w prev (colored)'!B10 -> 94.891892 | C10: ='Compare w prev (colored)'!C10 -> 95.945946 | D10: ='Compare w prev (colored)'!D10 -> 96.189189 | E10: ='Compare w prev (colored)'!E10 -> 83.783784 | G10: ='Compare w prev (colored)'!G10 -> 98.378378 | H10: ='Compare w prev (colored)'!H10 -> 97.810811 | I10: ='Compare w prev (colored)'!I10 -> 97.837838 | J10: ='Compare w prev (colored)'!J10 -> 97.810811 | K10: ='Compare w prev (colored)'!K10 -> 98.378378 | L10: ='Compare w prev (colored)'!L10 -> 97.837838 | M10: ='Compare w prev (colored)'!M10 -> 96.486486 | N10: ='Compare w prev (colored)'!N10 -> 96.189189 | ... X10: ='Compare w prev (colored)'!X10 -> 99.189189 | Z10: ='Compare w prev (colored)'!Z10 -> 98.918919 | AA10: ='Compare w prev (colored)'!AA10 -> 97.891892 | AB10: ='Compare w prev (colored)'!AB10 -> 99.189189 | AC10: ='Compare w prev (colored)'!AC10 -> 98.405405 | AD10: ='Compare w prev (colored)'!AD10 -> 97.567568 | AE10: ='Compare w prev (colored)'!AE10 -> 95.891892 | AF10: ='Compare w prev (colored)'!AF10 -> 98.378378 | AG10: ='Compare w prev (colored)'!AG10 -> 99.108108 | ... AS10: ='Compare w prev (colored)'!AS10 -> 98.378378
A11: PEMS | B11: ='Compare w prev (colored)'!B11 -> 71.098266 | C11: ='Compare w prev (colored)'!C11 -> 71.098266 | D11: ='Compare w prev (colored)'!D11 -> 75.086705 | E11: ='Compare w prev (colored)'!E11 -> 84.393064 | F11: ='Compare w prev (colored)'!F11 -> 99.82659 | G11: ='Compare w prev (colored)'!G11 -> 97.687861 | H11: ='Compare w prev (colored)'!H11 -> 80.289017 | I11: ='Compare w prev (colored)'!I11 -> 98.265896 | ... X11: ='Compare w prev (colored)'!X11 -> 83.815029 | Z11: ='Compare w prev (colored)'!Z11 -> 89.017341 | AA11: ='Compare w prev (colored)'!AA11 -> 90.982659 | AB11: ='Compare w prev (colored)'!AB11 -> 89.017341 | AC11: ='Compare w prev (colored)'!AC11 -> 80.924855 | AD11: ='Compare w prev (colored)'!AD11 -> 89.017341 | AE11: ='Compare w prev (colored)'!AE11 -> 86.011561 | AF11: ='Compare w prev (colored)'!AF11 -> 87.861272 | AG11: ='Compare w prev (colored)'!AG11 -> 85.895954 | ... AS11: ='Compare w prev (colored)'!AS11 -> 90.17341
A12: SRS1 | B12: ='Compare w prev (colored)'!B12 -> 77.713311 | C12: ='Compare w prev (colored)'!C12 -> 77.474403 | D12: ='Compare w prev (colored)'!D12 -> 90.784983 | E12: ='Compare w prev (colored)'!E12 -> 85.665529 | F12: ='Compare w prev (colored)'!F12 -> 87.883959 | G12: ='Compare w prev (colored)'!G12 -> 89.078498 | H12: ='Compare w prev (colored)'!H12 -> 86.68942 | I12: ='Compare w prev (colored)'!I12 -> 86.68942 | ... X12: ='Compare w prev (colored)'!X12 -> 91.808874 | Z12: ='Compare w prev (colored)'!Z12 -> 89.761092 | AA12: ='Compare w prev (colored)'!AA12 -> 93.105802 | AB12: ='Compare w prev (colored)'!AB12 -> 92.150171 | AC12: ='Compare w prev (colored)'!AC12 -> 88.703072 | AD12: ='Compare w prev (colored)'!AD12 -> 75.085324 | AE12: ='Compare w prev (colored)'!AE12 -> 89.590444 | AF12: ='Compare w prev (colored)'!AF12 -> 92.150171 | AG12: ='Compare w prev (colored)'!AG12 -> 92.491468 | ... AS12: ='Compare w prev (colored)'!AS12 -> 92.832765
A13: SRS2 | B13: ='Compare w prev (colored)'!B13 -> 53.888889 | C13: ='Compare w prev (colored)'!C13 -> 53.888889 | D13: ='Compare w prev (colored)'!D13 -> 54.444444 | E13: ='Compare w prev (colored)'!E13 -> 55.555556 | F13: ='Compare w prev (colored)'!F13 -> 50.444444 | G13: ='Compare w prev (colored)'!G13 -> 54.444444 | H13: ='Compare w prev (colored)'!H13 -> 58.888889 | I13: ='Compare w prev (colored)'!I13 -> 58.888889 | ... X13: ='Compare w prev (colored)'!X13 -> 61.666667 | Z13: ='Compare w prev (colored)'!Z13 -> 63.888889 | AA13: ='Compare w prev (colored)'!AA13 -> 65.611111 | AB13: ='Compare w prev (colored)'!AB13 -> 60.555556 | AC13: ='Compare w prev (colored)'!AC13 -> 54.388889 | AD13: ='Compare w prev (colored)'!AD13 -> 59.444444 | AE13: ='Compare w prev (colored)'!AE13 -> 55 | AF13: ='Compare w prev (colored)'!AF13 -> 60 | AG13: ='Compare w prev (colored)'!AG13 -> 58.277778 | ... AS13: ='Compare w prev (colored)'!AS13 -> 62.222222
A14: SAD | B14: ='Compare w prev (colored)'!B14 -> 96.298317 | C14: ='Compare w prev (colored)'!C14 -> 97.226012 | D14: ='Compare w prev (colored)'!D14 -> 99.199636 | E14: ='Compare w prev (colored)'!E14 -> 99.226921 | G14: ='Compare w prev (colored)'!G14 -> 99.135971 | H14: ='Compare w prev (colored)'!H14 -> 98.8995 | I14: ='Compare w prev (colored)'!I14 -> 99.135971 | J14: ='Compare w prev (colored)'!J14 -> 99.299682 | K14: ='Compare w prev (colored)'!K14 -> 99.04502 | L14: ='Compare w prev (colored)'!L14 -> 96.680309 | M14: ='Compare w prev (colored)'!M14 -> 96.953161 | N14: ='Compare w prev (colored)'!N14 -> 100 | ... X14: ='Compare w prev (colored)'!X14 -> 99.90905 | Z14: ='Compare w prev (colored)'!Z14 -> 98.044566 | AA14: ='Compare w prev (colored)'!AA14 -> 99.799909 | AB14: ='Compare w prev (colored)'!AB14 -> 99.545248 | AC14: ='Compare w prev (colored)'!AC14 -> 100 | AD14: ='Compare w prev (colored)'!AD14 -> 99.454297 | AE14: ='Compare w prev (colored)'!AE14 -> 100 | AF14: ='Compare w prev (colored)'!AF14 -> 98.999545 | AG14: ='Compare w prev (colored)'!AG14 -> 97.899045 | ... AS14: ='Compare w prev (colored)'!AS14 -> 95.81628
A15: UW | B15: ='Compare w prev (colored)'!B15 -> 90.3125 | C15: ='Compare w prev (colored)'!C15 -> 90.3125 | D15: ='Compare w prev (colored)'!D15 -> 94.40625 | E15: ='Compare w prev (colored)'!E15 -> 94.0625 | F15: ='Compare w prev (colored)'!F15 -> 94.875 | G15: ='Compare w prev (colored)'!G15 -> 94.0625 | H15: ='Compare w prev (colored)'!H15 -> 90.90625 | I15: ='Compare w prev (colored)'!I15 -> 94.375 | ... X15: ='Compare w prev (colored)'!X15 -> 91.25 | Z15: ='Compare w prev (colored)'!Z15 -> 94.375 | AA15: ='Compare w prev (colored)'!AA15 -> 88.1875 | AB15: ='Compare w prev (colored)'!AB15 -> 90.625 | AC15: ='Compare w prev (colored)'!AC15 -> 85.3125 | AD15: ='Compare w prev (colored)'!AD15 -> 79.6875 | AE15: ='Compare w prev (colored)'!AE15 -> 85 | AF15: ='Compare w prev (colored)'!AF15 -> 89.6875 | AG15: ='Compare w prev (colored)'!AG15 -> 85.3125 | ... AS15: ='Compare w prev (colored)'!AS15 -> 95.3125
A16: AWR | C16: ='Compare w prev (colored)'!C16 -> 98.666667 | D16: ='Compare w prev (colored)'!D16 -> 99.333333 | E16: ='Compare w prev (colored)'!E16 -> 99.333333 | F16: ='Compare w prev (colored)'!F16 -> 99.566667 | G16: ='Compare w prev (colored)'!G16 -> 99.333333 | H16: ='Compare w prev (colored)'!H16 -> 99 | I16: ='Compare w prev (colored)'!I16 -> 99.333333 | J16: ='Compare w prev (colored)'!J16 -> 99.333333 | ... M16: ='Compare w prev (colored)'!M16 -> 97.666667 | O16: ='Compare w prev (colored)'!O16 -> 98.333333 | Q16: ='Compare w prev (colored)'!Q16 -> 99 | S16: ='Compare w prev (colored)'!S16 -> 96.166667 | T16: ='Compare w prev (colored)'!T16 -> 98.666667 | W16: ='Compare w prev (colored)'!W16 -> 98.666667 | X16: ='Compare w prev (colored)'!X16 -> 99 | Z16: ='Compare w prev (colored)'!Z16 -> 99.333333 | AB16: ='Compare w prev (colored)'!AB16 -> 99 | AD16: ='Compare w prev (colored)'!AD16 -> 92.333333 | AF16: ='Compare w prev (colored)'!AF16 -> 98.666667 | AG16: ='Compare w prev (colored)'!AG16 -> 98 | AH16: ='Compare w prev (colored)'!AH16 -> 98.666667 | AI16: ='Compare w prev (colored)'!AI16 -> 97.666667 | AJ16: ='Compare w prev (colored)'!AJ16 -> 98.666667 | AL16: ='Compare w prev (colored)'!AL16 -> 93.333333 | AM16: ='Compare w prev (colored)'!AM16 -> 98.666667 | AO16: ='Compare w prev (colored)'!AO16 -> 99 | AP16: ='Compare w prev (colored)'!AP16 -> 99.666667 | AQ16: ='Compare w prev (colored)'!AQ16 -> 99 | AR16: ='Compare w prev (colored)'!AR16 -> 97 | AS16: ='Compare w prev (colored)'!AS16 -> 99.333333
A17: AF | C17: ='Compare w prev (colored)'!C17 -> 20 | D17: ='Compare w prev (colored)'!D17 -> 20 | E17: ='Compare w prev (colored)'!E17 -> 6.6666667 | F17: ='Compare w prev (colored)'!F17 -> 28 | G17: ='Compare w prev (colored)'!G17 -> 20 | H17: ='Compare w prev (colored)'!H17 -> 13.333333 | I17: ='Compare w prev (colored)'!I17 -> 26.666667 | J17: ='Compare w prev (colored)'!J17 -> 6.6666667 | ... M17: ='Compare w prev (colored)'!M17 -> 53.333333 | O17: ='Compare w prev (colored)'!O17 -> 73.333333 | Q17: ='Compare w prev (colored)'!Q17 -> 60 | S17: ='Compare w prev (colored)'!S17 -> 33.333333 | T17: ='Compare w prev (colored)'!T17 -> 66.666667 | W17: ='Compare w prev (colored)'!W17 -> 73.333333 | X17: ='Compare w prev (colored)'!X17 -> 40 | Z17: ='Compare w prev (colored)'!Z17 -> 66.666667 | AB17: ='Compare w prev (colored)'!AB17 -> 66.666667 | AD17: ='Compare w prev (colored)'!AD17 -> 73.333333 | AF17: ='Compare w prev (colored)'!AF17 -> 80 | AG17: ='Compare w prev (colored)'!AG17 -> 46.666667 | AH17: ='Compare w prev (colored)'!AH17 -> 73.333333 | AI17: ='Compare w prev (colored)'!AI17 -> 53.333333 | AJ17: ='Compare w prev (colored)'!AJ17 -> 80 | AL17: ='Compare w prev (colored)'!AL17 -> 33.333333 | AM17: ='Compare w prev (colored)'!AM17 -> 66.666667 | AO17: ='Compare w prev (colored)'!AO17 -> 66.666667 | AP17: ='Compare w prev (colored)'!AP17 -> 33.333333 | AQ17: ='Compare w prev (colored)'!AQ17 -> 46.666667 | AR17: ='Compare w prev (colored)'!AR17 -> 67.333333 | AS17: ='Compare w prev (colored)'!AS17 -> 66.666667
A18: BM | C18: ='Compare w prev (colored)'!C18 -> 97.5 | D18: ='Compare w prev (colored)'!D18 -> 100 | E18: ='Compare w prev (colored)'!E18 -> 100 | F18: ='Compare w prev (colored)'!F18 -> 99 | G18: ='Compare w prev (colored)'!G18 -> 100 | H18: ='Compare w prev (colored)'!H18 -> 100 | I18: ='Compare w prev (colored)'!I18 -> 100 | J18: ='Compare w prev (colored)'!J18 -> 100 | ... M18: ='Compare w prev (colored)'!M18 -> 87.5 | O18: ='Compare w prev (colored)'!O18 -> 100 | Q18: ='Compare w prev (colored)'!Q18 -> 100 | S18: ='Compare w prev (colored)'!S18 -> 100 | T18: ='Compare w prev (colored)'!T18 -> 100 | W18: ='Compare w prev (colored)'!W18 -> 100 | X18: ='Compare w prev (colored)'!X18 -> 100 | Z18: ='Compare w prev (colored)'!Z18 -> 100 | AB18: ='Compare w prev (colored)'!AB18 -> 100 | AD18: ='Compare w prev (colored)'!AD18 -> 95 | AF18: ='Compare w prev (colored)'!AF18 -> 100 | AG18: ='Compare w prev (colored)'!AG18 -> 90 | AH18: ='Compare w prev (colored)'!AH18 -> 100 | AI18: ='Compare w prev (colored)'!AI18 -> 92.5 | AJ18: ='Compare w prev (colored)'!AJ18 -> 85 | AL18: ='Compare w prev (colored)'!AL18 -> 92.5 | AM18: ='Compare w prev (colored)'!AM18 -> 100 | AO18: ='Compare w prev (colored)'!AO18 -> 97.5 | AP18: ='Compare w prev (colored)'!AP18 -> 100 | AQ18: ='Compare w prev (colored)'!AQ18 -> 100 | AR18: ='Compare w prev (colored)'!AR18 -> 100 | AS18: ='Compare w prev (colored)'!AS18 -> 100
A19: CT | C19: ='Compare w prev (colored)'!C19 -> 98.816156 | D19: ='Compare w prev (colored)'!D19 -> 98.753482 | E19: ='Compare w prev (colored)'!E19 -> 99.303621 | G19: ='Compare w prev (colored)'!G19 -> 99.303621 | H19: ='Compare w prev (colored)'!H19 -> 98.600279 | I19: ='Compare w prev (colored)'!I19 -> 99.164345 | J19: ='Compare w prev (colored)'!J19 -> 99.199164 | K19: ='Compare w prev (colored)'!K19 -> 99.373259 | L19: ='Compare w prev (colored)'!L19 -> 97.346797 | M19: ='Compare w prev (colored)'!M19 -> 98.119777 | O19: ='Compare w prev (colored)'!O19 -> 98.955432 | Q19: ='Compare w prev (colored)'!Q19 -> 97.980501 | S19: ='Compare w prev (colored)'!S19 -> 97.980501 | T19: ='Compare w prev (colored)'!T19 -> 98.746518 | W19: ='Compare w prev (colored)'!W19 -> 99.303621 | Y19: ='Compare w prev (colored)'!Y19 -> 98.746518 | Z19: ='Compare w prev (colored)'!Z19 -> 99.164345 | AB19: ='Compare w prev (colored)'!AB19 -> 99.373259 | AD19: ='Compare w prev (colored)'!AD19 -> 97.284123 | AF19: ='Compare w prev (colored)'!AF19 -> 98.467967 | AG19: ='Compare w prev (colored)'!AG19 -> 98.328691 | AH19: ='Compare w prev (colored)'!AH19 -> 98.955432 | AI19: ='Compare w prev (colored)'!AI19 -> 97.346797 | AJ19: ='Compare w prev (colored)'!AJ19 -> 98.398329 | AL19: ='Compare w prev (colored)'!AL19 -> 98.259053 | AM19: ='Compare w prev (colored)'!AM19 -> 99.373259 | AO19: ='Compare w prev (colored)'!AO19 -> 98.885794 | AP19: ='Compare w prev (colored)'!AP19 -> 99.791086 | AQ19: ='Compare w prev (colored)'!AQ19 -> 99.791086 | AR19: ='Compare w prev (colored)'!AR19 -> 98.997214 | AS19: ='Compare w prev (colored)'!AS19 -> 99.512535
A20: CR | C20: ='Compare w prev (colored)'!C20 -> 100 | D20: ='Compare w prev (colored)'!D20 -> 98.611111 | E20: ='Compare w prev (colored)'!E20 -> 100 | F20: ='Compare w prev (colored)'!F20 -> 100 | G20: ='Compare w prev (colored)'!G20 -> 100 | H20: ='Compare w prev (colored)'!H20 -> 98.611111 | I20: ='Compare w prev (colored)'!I20 -> 100 | J20: ='Compare w prev (colored)'!J20 -> 98.611111 | ... M20: ='Compare w prev (colored)'!M20 -> 91.666667 | O20: ='Compare w prev (colored)'!O20 -> 93.055556 | Q20: ='Compare w prev (colored)'!Q20 -> 97.222222 | S20: ='Compare w prev (colored)'!S20 -> 87.5 | T20: ='Compare w prev (colored)'!T20 -> 97.222222 | W20: ='Compare w prev (colored)'!W20 -> 97.222222 | X20: ='Compare w prev (colored)'!X20 -> 98.611111 | Z20: ='Compare w prev (colored)'!Z20 -> 91.666667 | AB20: ='Compare w prev (colored)'!AB20 -> 98.611111 | AD20: ='Compare w prev (colored)'!AD20 -> 90.277778 | AF20: ='Compare w prev (colored)'!AF20 -> 98.611111 | AG20: ='Compare w prev (colored)'!AG20 -> 84.722222 | AH20: ='Compare w prev (colored)'!AH20 -> 97.222222 | AI20: ='Compare w prev (colored)'!AI20 -> 84.722222 | AJ20: ='Compare w prev (colored)'!AJ20 -> 97.222222 | AL20: ='Compare w prev (colored)'!AL20 -> 8.3333333 | AM20: ='Compare w prev (colored)'!AM20 -> 97.222222 | AO20: ='Compare w prev (colored)'!AO20 -> 97.222222 | AP20: ='Compare w prev (colored)'!AP20 -> 100 | AQ20: ='Compare w prev (colored)'!AQ20 -> 100 | AR20: ='Compare w prev (colored)'!AR20 -> 98.611111 | AS20: ='Compare w prev (colored)'!AS20 -> 100
A21: DDG | C21: ='Compare w prev (colored)'!C21 -> 58 | D21: ='Compare w prev (colored)'!D21 -> 52 | E21: ='Compare w prev (colored)'!E21 -> 52 | F21: ='Compare w prev (colored)'!F21 -> 49.8 | G21: ='Compare w prev (colored)'!G21 -> 70 | H21: ='Compare w prev (colored)'!H21 -> 68 | I21: ='Compare w prev (colored)'!I21 -> 68 | J21: ='Compare w prev (colored)'!J21 -> 64 | ... M21: ='Compare w prev (colored)'!M21 -> 66 | O21: ='Compare w prev (colored)'!O21 -> 56 | Q21: ='Compare w prev (colored)'!Q21 -> 68 | S21: ='Compare w prev (colored)'!S21 -> 56 | T21: ='Compare w prev (colored)'!T21 -> 68 | W21: ='Compare w prev (colored)'!W21 -> 66 | Y21: ='Compare w prev (colored)'!Y21 -> 24 | Z21: ='Compare w prev (colored)'!Z21 -> 74 | AB21: ='Compare w prev (colored)'!AB21 -> 74 | AD21: ='Compare w prev (colored)'!AD21 -> 42 | AF21: ='Compare w prev (colored)'!AF21 -> 42 | AG21: ='Compare w prev (colored)'!AG21 -> 44 | AH21: ='Compare w prev (colored)'!AH21 -> 72 | AI21: ='Compare w prev (colored)'!AI21 -> 24 | AJ21: ='Compare w prev (colored)'!AJ21 -> 40 | AL21: ='Compare w prev (colored)'!AL21 -> 50 | AM21: ='Compare w prev (colored)'!AM21 -> 66 | AO21: ='Compare w prev (colored)'!AO21 -> 60 | AP21: ='Compare w prev (colored)'!AP21 -> 68 | AQ21: ='Compare w prev (colored)'!AQ21 -> 76 | AR21: ='Compare w prev (colored)'!AR21 -> 62 | AS21: ='Compare w prev (colored)'!AS21 -> 50
A22: EW | C22: ='Compare w prev (colored)'!C22 -> 61.832061 | D22: ='Compare w prev (colored)'!D22 -> 78.625954 | E22: ='Compare w prev (colored)'!E22 -> 91.603053 | F22: ='Compare w prev (colored)'!F22 -> 89.465649 | G22: ='Compare w prev (colored)'!G22 -> 97.709924 | H22: ='Compare w prev (colored)'!H22 -> 98.473282 | I22: ='Compare w prev (colored)'!I22 -> 98.473282 | J22: ='Compare w prev (colored)'!J22 -> 96.183206 | ... M22: ='Compare w prev (colored)'!M22 -> 42.748092 | O22: ='Compare w prev (colored)'!O22 -> 54.198473 | Q22: ='Compare w prev (colored)'!Q22 -> 66.412214 | S22: ='Compare w prev (colored)'!S22 -> 58.778626 | T22: ='Compare w prev (colored)'!T22 -> 63.358779 | W22: ='Compare w prev (colored)'!W22 -> 64.122137 | Y22: ='Compare w prev (colored)'!Y22 -> 41.221374 | Z22: ='Compare w prev (colored)'!Z22 -> 81.679389 | AB22: ='Compare w prev (colored)'!AB22 -> 61.068702 | AD22: ='Compare w prev (colored)'!AD22 -> 63.358779 | AF22: ='Compare w prev (colored)'!AF22 -> 70.992366 | AG22: ='Compare w prev (colored)'!AG22 -> 54.961832 | AH22: ='Compare w prev (colored)'!AH22 -> 58.015267 | AI22: ='Compare w prev (colored)'!AI22 -> 54.198473 | AJ22: ='Compare w prev (colored)'!AJ22 -> 57.251908 | AL22: ='Compare w prev (colored)'!AL22 -> 48.091603 | AM22: ='Compare w prev (colored)'!AM22 -> 66.412214 | AO22: ='Compare w prev (colored)'!AO22 -> 59.541985 | AP22: ='Compare w prev (colored)'!AP22 -> 83.969466 | AQ22: ='Compare w prev (colored)'!AQ22 -> 82.442748 | AR22: ='Compare w prev (colored)'!AR22 -> 87.022901 | AS22: ='Compare w prev (colored)'!AS22 -> 88.549618
A23: EP | C23: ='Compare w prev (colored)'!C23 -> 96.376812 | D23: ='Compare w prev (colored)'!D23 -> 98.550725 | E23: ='Compare w prev (colored)'!E23 -> 99.275362 | F23: ='Compare w prev (colored)'!F23 -> 99.782609 | G23: ='Compare w prev (colored)'!G23 -> 100 | H23: ='Compare w prev (colored)'!H23 -> 100 | I23: ='Compare w prev (colored)'!I23 -> 100 | J23: ='Compare w prev (colored)'!J23 -> 100 | ... M23: ='Compare w prev (colored)'!M23 -> 65.217391 | O23: ='Compare w prev (colored)'!O23 -> 97.101449 | Q23: ='Compare w prev (colored)'!Q23 -> 66.666667 | S23: ='Compare w prev (colored)'!S23 -> 78.115942 | T23: ='Compare w prev (colored)'!T23 -> 96.376812 | W23: ='Compare w prev (colored)'!W23 -> 96.376812 | X23: ='Compare w prev (colored)'!X23 -> 98.550725 | Z23: ='Compare w prev (colored)'!Z23 -> 100 | AB23: ='Compare w prev (colored)'!AB23 -> 94.927536 | AD23: ='Compare w prev (colored)'!AD23 -> 92.753623 | AF23: ='Compare w prev (colored)'!AF23 -> 92.753623 | AG23: ='Compare w prev (colored)'!AG23 -> 73.188406 | AH23: ='Compare w prev (colored)'!AH23 -> 95.652174 | AI23: ='Compare w prev (colored)'!AI23 -> 65.942029 | AJ23: ='Compare w prev (colored)'!AJ23 -> 98.550725 | AL23: ='Compare w prev (colored)'!AL23 -> 85.507246 | AM23: ='Compare w prev (colored)'!AM23 -> 89.855072 | AO23: ='Compare w prev (colored)'!AO23 -> 80.434783 | AP23: ='Compare w prev (colored)'!AP23 -> 99.275362 | AQ23: ='Compare w prev (colored)'!AQ23 -> 97.826087 | AR23: ='Compare w prev (colored)'!AR23 -> 97.101449 | AS23: ='Compare w prev (colored)'!AS23 -> 99.275362
A24: ER | C24: ='Compare w prev (colored)'!C24 -> 91.481481 | D24: ='Compare w prev (colored)'!D24 -> 94.074074 | E24: ='Compare w prev (colored)'!E24 -> 98.888889 | F24: ='Compare w prev (colored)'!F24 -> 98.518519 | G24: ='Compare w prev (colored)'!G24 -> 98.888889 | H24: ='Compare w prev (colored)'!H24 -> 98.518519 | I24: ='Compare w prev (colored)'!I24 -> 98.888889 | J24: ='Compare w prev (colored)'!J24 -> 98.888889 | ... M24: ='Compare w prev (colored)'!M24 -> 91.851852 | O24: ='Compare w prev (colored)'!O24 -> 94.444444 | Q24: ='Compare w prev (colored)'!Q24 -> 77.777778 | S24: ='Compare w prev (colored)'!S24 -> 94.074074 | T24: ='Compare w prev (colored)'!T24 -> 95.555556 | W24: ='Compare w prev (colored)'!W24 -> 97.407407 | Y24: ='Compare w prev (colored)'!Y24 -> 91.481481 | Z24: ='Compare w prev (colored)'!Z24 -> 85.925926 | AB24: ='Compare w prev (colored)'!AB24 -> 96.296296 | AD24: ='Compare w prev (colored)'!AD24 -> 95.925926 | AF24: ='Compare w prev (colored)'!AF24 -> 96.296296 | AG24: ='Compare w prev (colored)'!AG24 -> 94.074074 | AH24: ='Compare w prev (colored)'!AH24 -> 97.407407 | AI24: ='Compare w prev (colored)'!AI24 -> 92.592593 | AJ24: ='Compare w prev (colored)'!AJ24 -> 96.666667 | AL24: ='Compare w prev (colored)'!AL24 -> 95.925926 | AM24: ='Compare w prev (colored)'!AM24 -> 96.296296 | AO24: ='Compare w prev (colored)'!AO24 -> 94.814815 | AP24: ='Compare w prev (colored)'!AP24 -> 95.185185 | AQ24: ='Compare w prev (colored)'!AQ24 -> 87.777778 | AR24: ='Compare w prev (colored)'!AR24 -> 91.518519 | AS24: ='Compare w prev (colored)'!AS24 -> 97.037037
A25: FM | C25: ='Compare w prev (colored)'!C25 -> 53 | D25: ='Compare w prev (colored)'!D25 -> 61 | E25: ='Compare w prev (colored)'!E25 -> 57 | F25: ='Compare w prev (colored)'!F25 -> 55.2 | G25: ='Compare w prev (colored)'!G25 -> 61 | H25: ='Compare w prev (colored)'!H25 -> 55 | I25: ='Compare w prev (colored)'!I25 -> 55 | J25: ='Compare w prev (colored)'!J25 -> 56 | ... M25: ='Compare w prev (colored)'!M25 -> 62 | O25: ='Compare w prev (colored)'!O25 -> 64 | Q25: ='Compare w prev (colored)'!Q25 -> 63 | S25: ='Compare w prev (colored)'!S25 -> 59.4 | T25: ='Compare w prev (colored)'!T25 -> 66 | W25: ='Compare w prev (colored)'!W25 -> 67 | X25: ='Compare w prev (colored)'!X25 -> 61 | Z25: ='Compare w prev (colored)'!Z25 -> 68 | AB25: ='Compare w prev (colored)'!AB25 -> 67 | AD25: ='Compare w prev (colored)'!AD25 -> 72 | AF25: ='Compare w prev (colored)'!AF25 -> 66 | AG25: ='Compare w prev (colored)'!AG25 -> 64 | AH25: ='Compare w prev (colored)'!AH25 -> 64 | AI25: ='Compare w prev (colored)'!AI25 -> 62 | AJ25: ='Compare w prev (colored)'!AJ25 -> 63 | AL25: ='Compare w prev (colored)'!AL25 -> 57 | AM25: ='Compare w prev (colored)'!AM25 -> 66 | AO25: ='Compare w prev (colored)'!AO25 -> 64 | AP25: ='Compare w prev (colored)'!AP25 -> 64 | AQ25: ='Compare w prev (colored)'!AQ25 -> 67 | AR25: ='Compare w prev (colored)'!AR25 -> 69 | AS25: ='Compare w prev (colored)'!AS25 -> 66
A26: HMD | C26: ='Compare w prev (colored)'!C26 -> 18.918919 | D26: ='Compare w prev (colored)'!D26 -> 50 | E26: ='Compare w prev (colored)'!E26 -> 51.351351 | F26: ='Compare w prev (colored)'!F26 -> 39.72973 | G26: ='Compare w prev (colored)'!G26 -> 48.648649 | H26: ='Compare w prev (colored)'!H26 -> 21.621622 | I26: ='Compare w prev (colored)'!I26 -> 51.351351 | J26: ='Compare w prev (colored)'!J26 -> 36.486486 | ... M26: ='Compare w prev (colored)'!M26 -> 66.216216 | O26: ='Compare w prev (colored)'!O26 -> 66.216216 | Q26: ='Compare w prev (colored)'!Q26 -> 70.27027 | S26: ='Compare w prev (colored)'!S26 -> 50 | T26: ='Compare w prev (colored)'!T26 -> 72.972973 | W26: ='Compare w prev (colored)'!W26 -> 66.216216 | X26: ='Compare w prev (colored)'!X26 -> 52.702703 | Z26: ='Compare w prev (colored)'!Z26 -> 48.648649 | AB26: ='Compare w prev (colored)'!AB26 -> 72.972973 | AD26: ='Compare w prev (colored)'!AD26 -> 71.621622 | AF26: ='Compare w prev (colored)'!AF26 -> 63.513514 | AG26: ='Compare w prev (colored)'!AG26 -> 58.108108 | AH26: ='Compare w prev (colored)'!AH26 -> 66.216216 | AI26: ='Compare w prev (colored)'!AI26 -> 58.108108 | AJ26: ='Compare w prev (colored)'!AJ26 -> 63.513514 | AL26: ='Compare w prev (colored)'!AL26 -> 18.918919 | AM26: ='Compare w prev (colored)'!AM26 -> 70.27027 | AO26: ='Compare w prev (colored)'!AO26 -> 58.108108 | AP26: ='Compare w prev (colored)'!AP26 -> 48.648649 | AQ26: ='Compare w prev (colored)'!AQ26 -> 45.945946 | AR26: ='Compare w prev (colored)'!AR26 -> 71.621622 | AS26: ='Compare w prev (colored)'!AS26 -> 60.810811
A27: IW | C27: ='Compare w prev (colored)'!C27 -> 48.692 | D27: ='Compare w prev (colored)'!D27 -> 10 | E27: ='Compare w prev (colored)'!E27 -> 38.524 | G27: ='Compare w prev (colored)'!G27 -> 66.796 | H27: ='Compare w prev (colored)'!H27 -> 67.9 | I27: ='Compare w prev (colored)'!I27 -> 67.052 | J27: ='Compare w prev (colored)'!J27 -> 66.7 | K27: ='Compare w prev (colored)'!K27 -> 65.744 | L27: ='Compare w prev (colored)'!L27 -> 10 | M27: ='Compare w prev (colored)'!M27 -> 18.996 | O27: ='Compare w prev (colored)'!O27 -> 71.676 | Q27: ='Compare w prev (colored)'!Q27 -> 72.424 | S27: ='Compare w prev (colored)'!S27 -> 10 | T27: ='Compare w prev (colored)'!T27 -> 64.024 | W27: ='Compare w prev (colored)'!W27 -> 75.588 | X27: ='Compare w prev (colored)'!X27 -> 10 | Z27: ='Compare w prev (colored)'!Z27 -> 10.012 | AB27: ='Compare w prev (colored)'!AB27 -> 64.192 | AD27: ='Compare w prev (colored)'!AD27 -> 65.244 | AF27: ='Compare w prev (colored)'!AF27 -> 64.868 | AG27: ='Compare w prev (colored)'!AG27 -> 10 | AH27: ='Compare w prev (colored)'!AH27 -> 73.712 | AI27: ='Compare w prev (colored)'!AI27 -> 10 | AJ27: ='Compare w prev (colored)'!AJ27 -> 60.936 | AL27: ='Compare w prev (colored)'!AL27 -> 10 | AM27: ='Compare w prev (colored)'!AM27 -> 61.396 | AO27: ='Compare w prev (colored)'!AO27 -> 73.436 | AP27: ='Compare w prev (colored)'!AP27 -> 66.752 | AQ27: ='Compare w prev (colored)'!AQ27 -> 67.18 | AR27: ='Compare w prev (colored)'!AR27 -> 14.3 | AS27: ='Compare w prev (colored)'!AS27 -> 68.244
A28: LIB | C28: ='Compare w prev (colored)'!C28 -> 87.222222 | D28: ='Compare w prev (colored)'!D28 -> 83.888889 | E28: ='Compare w prev (colored)'!E28 -> 90.555556 | F28: ='Compare w prev (colored)'!F28 -> 92.666667 | G28: ='Compare w prev (colored)'!G28 -> 94.444444 | H28: ='Compare w prev (colored)'!H28 -> 93.277778 | I28: ='Compare w prev (colored)'!I28 -> 93.333333 | J28: ='Compare w prev (colored)'!J28 -> 92.777778 | ... M28: ='Compare w prev (colored)'!M28 -> 70.555556 | O28: ='Compare w prev (colored)'!O28 -> 89.444444 | Q28: ='Compare w prev (colored)'!Q28 -> 34.444444 | S28: ='Compare w prev (colored)'!S28 -> 77.833333 | T28: ='Compare w prev (colored)'!T28 -> 88.333333 | W28: ='Compare w prev (colored)'!W28 -> 90 | X28: ='Compare w prev (colored)'!X28 -> 92.777778 | Z28: ='Compare w prev (colored)'!Z28 -> 95.555556 | AB28: ='Compare w prev (colored)'!AB28 -> 88.333333 | AD28: ='Compare w prev (colored)'!AD28 -> 93.333333 | AF28: ='Compare w prev (colored)'!AF28 -> 90 | AG28: ='Compare w prev (colored)'!AG28 -> 76.111111 | AH28: ='Compare w prev (colored)'!AH28 -> 90.555556 | AI28: ='Compare w prev (colored)'!AI28 -> 81.111111 | AJ28: ='Compare w prev (colored)'!AJ28 -> 81.666667 | AL28: ='Compare w prev (colored)'!AL28 -> 79.444444 | AM28: ='Compare w prev (colored)'!AM28 -> 87.777778 | AO28: ='Compare w prev (colored)'!AO28 -> 91.666667 | AP28: ='Compare w prev (colored)'!AP28 -> 97.222222 | AQ28: ='Compare w prev (colored)'!AQ28 -> 97.222222 | AR28: ='Compare w prev (colored)'!AR28 -> 90 | AS28: ='Compare w prev (colored)'!AS28 -> 91.666667
A29: LSST | C29: ='Compare w prev (colored)'!C29 -> 55.109489 | D29: ='Compare w prev (colored)'!D29 -> 54.099757 | E29: ='Compare w prev (colored)'!E29 -> 64.030819 | F29: ='Compare w prev (colored)'!F29 -> 63.694242 | G29: ='Compare w prev (colored)'!G29 -> 66.382806 | H29: ='Compare w prev (colored)'!H29 -> 60.701541 | I29: ='Compare w prev (colored)'!I29 -> 66.504461 | J29: ='Compare w prev (colored)'!J29 -> 63.600973 | ... M29: ='Compare w prev (colored)'!M29 -> 34.022709 | O29: ='Compare w prev (colored)'!O29 -> 41.524736 | Q29: ='Compare w prev (colored)'!Q29 -> 34.184915 | S29: ='Compare w prev (colored)'!S29 -> 59.209246 | T29: ='Compare w prev (colored)'!T29 -> 44.120032 | W29: ='Compare w prev (colored)'!W29 -> 43.592863 | X29: ='Compare w prev (colored)'!X29 -> 66.3382 | Z29: ='Compare w prev (colored)'!Z29 -> 51.013788 | AB29: ='Compare w prev (colored)'!AB29 -> 44.444444 | AD29: ='Compare w prev (colored)'!AD29 -> 40.997567 | AF29: ='Compare w prev (colored)'!AF29 -> 41.240876 | AG29: ='Compare w prev (colored)'!AG29 -> 42.818329 | AH29: ='Compare w prev (colored)'!AH29 -> 41.768045 | AI29: ='Compare w prev (colored)'!AI29 -> 67.798054 | AJ29: ='Compare w prev (colored)'!AJ29 -> 56.731549 | AL29: ='Compare w prev (colored)'!AL29 -> 46.390916 | AM29: ='Compare w prev (colored)'!AM29 -> 38.077859 | AO29: ='Compare w prev (colored)'!AO29 -> 40.673155 | AP29: ='Compare w prev (colored)'!AP29 -> 60.665045 | AQ29: ='Compare w prev (colored)'!AQ29 -> 59.570154 | AR29: ='Compare w prev (colored)'!AR29 -> 60.300081 | AS29: ='Compare w prev (colored)'!AS29 -> 60.056772
A30: MI | C30: ='Compare w prev (colored)'!C30 -> 50 | D30: ='Compare w prev (colored)'!D30 -> 53 | E30: ='Compare w prev (colored)'!E30 -> 54 | F30: ='Compare w prev (colored)'!F30 -> 53.2 | G30: ='Compare w prev (colored)'!G30 -> 50 | H30: ='Compare w prev (colored)'!H30 -> 50 | I30: ='Compare w prev (colored)'!I30 -> 54 | J30: ='Compare w prev (colored)'!J30 -> 48 | ... M30: ='Compare w prev (colored)'!M30 -> 64 | O30: ='Compare w prev (colored)'!O30 -> 68 | Q30: ='Compare w prev (colored)'!Q30 -> 66 | S30: ='Compare w prev (colored)'!S30 -> 51 | T30: ='Compare w prev (colored)'!T30 -> 68 | W30: ='Compare w prev (colored)'!W30 -> 67 | X30: ='Compare w prev (colored)'!X30 -> 62 | Z30: ='Compare w prev (colored)'!Z30 -> 71 | AB30: ='Compare w prev (colored)'!AB30 -> 67 | AD30: ='Compare w prev (colored)'!AD30 -> 65 | AF30: ='Compare w prev (colored)'!AF30 -> 67 | AG30: ='Compare w prev (colored)'!AG30 -> 61 | AH30: ='Compare w prev (colored)'!AH30 -> 68 | AI30: ='Compare w prev (colored)'!AI30 -> 61 | AJ30: ='Compare w prev (colored)'!AJ30 -> 69 | AL30: ='Compare w prev (colored)'!AL30 -> 50 | AM30: ='Compare w prev (colored)'!AM30 -> 67 | AO30: ='Compare w prev (colored)'!AO30 -> 67 | AP30: ='Compare w prev (colored)'!AP30 -> 64 | AQ30: ='Compare w prev (colored)'!AQ30 -> 67 | AR30: ='Compare w prev (colored)'!AR30 -> 62 | AS30: ='Compare w prev (colored)'!AS30 -> 67
A31: NATO | C31: ='Compare w prev (colored)'!C31 -> 88.333333 | D31: ='Compare w prev (colored)'!D31 -> 83.333333 | E31: ='Compare w prev (colored)'!E31 -> 89.444444 | F31: ='Compare w prev (colored)'!F31 -> 89.222222 | G31: ='Compare w prev (colored)'!G31 -> 91.111111 | H31: ='Compare w prev (colored)'!H31 -> 87.222222 | I31: ='Compare w prev (colored)'!I31 -> 90 | J31: ='Compare w prev (colored)'!J31 -> 91.722222 | ... M31: ='Compare w prev (colored)'!M31 -> 96.111111 | O31: ='Compare w prev (colored)'!O31 -> 97.222222 | Q31: ='Compare w prev (colored)'!Q31 -> 95 | S31: ='Compare w prev (colored)'!S31 -> 81.833333 | T31: ='Compare w prev (colored)'!T31 -> 98.333333 | W31: ='Compare w prev (colored)'!W31 -> 95.555556 | X31: ='Compare w prev (colored)'!X31 -> 95.555556 | Z31: ='Compare w prev (colored)'!Z31 -> 99.444444 | AB31: ='Compare w prev (colored)'!AB31 -> 96.111111 | AD31: ='Compare w prev (colored)'!AD31 -> 96.111111 | AF31: ='Compare w prev (colored)'!AF31 -> 93.333333 | AG31: ='Compare w prev (colored)'!AG31 -> 88.333333 | AH31: ='Compare w prev (colored)'!AH31 -> 93.888889 | AI31: ='Compare w prev (colored)'!AI31 -> 96.666667 | AJ31: ='Compare w prev (colored)'!AJ31 -> 80.555556 | AL31: ='Compare w prev (colored)'!AL31 -> 91.666667 | AM31: ='Compare w prev (colored)'!AM31 -> 96.111111 | AO31: ='Compare w prev (colored)'!AO31 -> 88.888889 | AP31: ='Compare w prev (colored)'!AP31 -> 98.888889 | AQ31: ='Compare w prev (colored)'!AQ31 -> 98.888889 | AR31: ='Compare w prev (colored)'!AR31 -> 94.444444 | AS31: ='Compare w prev (colored)'!AS31 -> 92.222222
