Workbook

Sheet Summary
B2: input projection | C2: Mamba structure | E2: output projection
B3: kernel size (H1) | C3: modular SSM (H2) | D3: skip connection (H3) | E3: aggregation (H4)
B4: ✔ : $k=0.02L$ ✘ : $k=3$ | C4: ✔ : modular TV/TI ✘ : TV only | D4: ✔ : not use D ✘ : use D | E4: ✔ : adaptive pool. ✘ : the others | F4: avg. accuracy (10) | G4: avg. accuracy | H4: avg. rank | I4: # win /draw | J4: # lose /draw | L4: acc diff | M4: rank diff
A5: MambaSL | B5: ✔ | C5: ✔ | D5: ✔ | E5: ✔ | F5: =Full!Z43 -> 78.778661 | G5: 79.802265 | H5: 2.4333333 | I5: . | J5: . | L5: . | M5: .
A6: \quad w/o H1 | B6: ✘ | C6: ✔ | D6: ✔ | E6: ✔ | F6: =Full!S43 -> 77.412559 | G6: 80.214932 | H6: 2.5333333 | I6: 25 | J6: 22 | L6: =G6-G$5 -> 0.41266732 | M6: =H6-H$5 -> 0.1
A7: \quad w/o H2 | B7: ✔ | C7: ✘ | D7: ✔ | E7: ✔ | F7: =Full!T43 -> 75.659251 | G7: 77.075214 | H7: 5.9333333 | I7: 30 | J7: 5 | L7: =G7-G$5 -> -2.7270515 | M7: =H7-H$5 -> 3.5
A8: \quad w/o H3 | B8: ✔ | C8: ✔ | D8: ✘ | E8: ✔ | F8: =Full!U43 -> 77.714771 | G8: 79.162988 | H8: 3.5 | I8: 22 | J8: 14 | L8: =G8-G$5 -> -0.63927649 | M8: =H8-H$5 -> 1.0666667
A9: \quad w/o H4 | B9: ✔ | C9: ✔ | D9: ✔ | E9: ✘ (fully connect) | F9: =Full!V43 -> 76.437547 | G9: 77.722172 | H9: 4.8666667 | I9: 24 | J9: 10 | L9: =G9-G$5 -> -2.0800927 | M9: =H9-H$5 -> 2.4333333
B10: ✔ | C10: ✔ | D10: ✔ | E10: ✘ (avg pooling) | F10: =Full!W43 -> 76.899752 | G10: 78.60967 | H10: 3.6 | I10: 22 | J10: 15 | L10: =G10-G$5 -> -1.1925945 | M10: =H10-H$5 -> 1.1666667
B11: ✔ | C11: ✔ | D11: ✔ | E11: ✘ (max pooling) | F11: =Full!X43 -> 76.448495 | G11: 78.535223 | H11: 3.9 | I11: 22 | J11: 12 | L11: =G11-G$5 -> -1.2670421 | M11: =H11-H$5 -> 1.4666667
B12: ✔ | C12: ✔ | D12: ✔ | E12: ✘ (last timestep) | F12: =Full!Y43 -> 75.85566 | G12: 76.848214 | H12: 4.8666667 | I12: 25 | J12: 9 | L12: =G12-G$5 -> -2.9540512 | M12: =H12-H$5 -> 2.4333333
A13: \quad only H2 | B13: ✘ | C13: ✔ | D13: ✘ | E13: ✘ (avg pooling) | F13: =Full!L43 -> 77.092283 | G13: =Full!$L$44 -> 77.93505 | H13: . | I13: 20 | J13: 13 | L13: =G13-G$5 -> -1.867215
A14: Mamba | B14: ✘ | C14: ✘ | D14: ✘ | E14: ✘ (fully connect) | F14: =Full!AA43 -> 73.285705 | G14: 74.242717 | H14: . | I14: 26 | J14: 5 | L14: =G14-G$5 -> -5.5595476
B18: input projection | C18: Mamba structure | E18: output projection
B19: kernel size (H1) | C19: modular SSM (H2) | D19: skip connection (H3) | E19: aggregation (H4)
B20: ✔ : $k=0.02L$ ✘ : $k=3$ | C20: ✔ : modular TV/TI ✘ : TV only | D20: ✔ : not use D ✘ : use D | E20: ✔ : adaptive pool. ✘ : the others | F20: avg. accuracy | G20: avg. rank | H20: # win /draw | I20: # lose /draw
A21: MambaSL | B21: ✔ | C21: ✔ | D21: ✔ | E21: ✔ | F21: 79.802265 | G21: 2.4333333 | H21: . | I21: .
A22: \quad w/o H1 | B22: ✘ | C22: ✔ | D22: ✔ | E22: ✔ | F22: 80.214932 | G22: 2.5333333 | H22: 25 | I22: 22
A23: \quad w/o H2 | B23: ✔ | C23: ✘ | D23: ✔ | E23: ✔ | F23: 77.075214 | G23: 5.9333333 | H23: 30 | I23: 5
A24: \quad w/o H3 | B24: ✔ | C24: ✔ | D24: ✘ | E24: ✔ | F24: 79.162988 | G24: 3.5 | H24: 22 | I24: 14
A25: \quad w/o H4 | B25: ✔ | C25: ✔ | D25: ✔ | E25: ✘ (fully connect) | F25: 77.722172 | G25: 4.8666667 | H25: 24 | I25: 10
B26: ✔ | C26: ✔ | D26: ✔ | E26: ✘ (avg pooling) | F26: 78.60967 | G26: 3.6 | H26: 22 | I26: 15
B27: ✔ | C27: ✔ | D27: ✔ | E27: ✘ (max pooling) | F27: 78.535223 | G27: 3.9 | H27: 22 | I27: 12
B28: ✔ | C28: ✔ | D28: ✔ | E28: ✘ (last timestep) | F28: 76.848214 | G28: 4.8666667 | H28: 25 | I28: 9
A29: \quad only H2 | B29: ✘ | C29: ✔ | D29: ✘ | E29: ✘ (avg pooling) | F29: 77.092283 | G29: . | H29: 20 | I29: 13
A30: Mamba | B30: ✘ | C30: ✘ | D30: ✘ | E30: ✘ (fully connect) | F30: 74.242717 | G30: . | H30: 26 | I30: 5

Sheet Full
C2: ablation | K2: additional | S2: ablation | AA2: additional
A3: Model | C3: w/o H1 | D3: w/o H2 | E3: w/o H3 | F3: w/o H4 | J3: proposed | K3: Mamba | L3: w/ H2 | M3: w/o H2 | S3: w/o H1 | T3: w/o H2 | U3: w/o H3 | V3: w/o H4 | Z3: proposed | AA3: Mamba | AB3: w/ H2 | AC3: w/o H2
A4: kernel size (H1) | B4: ✔ : $k=0.02L$ ✘ : $k=3$ | C4: ✘ | D4: ✔ | E4: ✔ | F4: ✔ | G4: ✔ | H4: ✔ | I4: ✔ | J4: ✔ | K4: ✘ | L4: ✘ | M4: ✔ | R4: kernel size (H1) \cmark : $k=0.02L$ \xmark : $k=3$ | S4: \xmark | T4: \cmark | U4: \cmark | V4: \cmark | W4: \cmark | X4: \cmark | Y4: \cmark | Z4: \cmark | AA4: \xmark | AB4: \xmark | AC4: \cmark
A5: modular SSM (H2) | B5: ✔ : modular TV/TI ✘ : TV only | C5: ✔ | D5: ✘ | E5: ✔ | F5: ✔ | G5: ✔ | H5: ✔ | I5: ✔ | J5: ✔ | K5: ✘ | L5: ✔ | M5: ✘ | R5: modular SSM (H2) \cmark : modular TV/TI \xmark : TV only | S5: \cmark | T5: \xmark | U5: \cmark | V5: \cmark | W5: \cmark | X5: \cmark | Y5: \cmark | Z5: \cmark | AA5: \xmark | AB5: \cmark | AC5: \xmark
A6: skip connection (H3) | B6: ✔ : not use D ✘ : use D | C6: ✔ | D6: ✔ | E6: ✘ | F6: ✔ | G6: ✔ | H6: ✔ | I6: ✔ | J6: ✔ | K6: ✘ | L6: ✘ | M6: ✔ | R6: skip connection (H3) \cmark : not use D \xmark : use D | S6: \cmark | T6: \cmark | U6: \xmark | V6: \cmark | W6: \cmark | X6: \cmark | Y6: \cmark | Z6: \cmark | AA6: \xmark | AB6: \xmark | AC6: \cmark
A7: aggregation (H4) | B7: ✔ : adaptive pool. ✘ : the others | C7: ✔ | D7: ✔ | E7: ✔ | F7: ✘ (full) | G7: ✘ (avg) | H7: ✘ (max) | I7: ✘ (last) | J7: ✔ | K7: ✘ (full) | L7: ✘ (avg) | M7: ✔ | R7: aggregation (H4) \cmark : adaptive pool. \xmark : the others | S7: \cmark | T7: \cmark | U7: \cmark | V7: \xmark (full) | W7: \xmark (avg) | X7: \xmark (max) | Y7: \xmark (last) | Z7: \cmark | AA7: \xmark (full) | AB7: \xmark (avg) | AC7: \cmark
B8: d_model | C8: 32..1024 | D8: 32..1024 | E8: 32..1024 | F8: 32..1024 | G8: 32..1024 | H8: 32..1024 | I8: 32..1024 | J8: 32..1024 | K8: 32..1024 | L8: 32..1024 | M8: 32..1024 | R8: d_model | S8: 32..1024 | T8: 32..1024 | U8: 32..1024 | V8: 32..1024 | W8: 32..1024 | X8: 32..1024 | Y8: 32..1024 | Z8: 32..1024 | AA8: 32..1024 | AB8: 32..1024 | AC8: 32..1024
B9: d_state | C9: 1..16 | D9: 1..16 | E9: 1..16 | F9: 1..16 | G9: 1..16 | H9: 1..16 | I9: 1..16 | J9: 1..16 | K9: 1..16 | L9: 1..16 | M9: 1..16 | R9: d_state | S9: 1..16 | T9: 1..16 | U9: 1..16 | V9: 1..16 | W9: 1..16 | X9: 1..16 | Y9: 1..16 | Z9: 1..16 | AA9: 1..16 | AB9: 1..16 | AC9: 1..16
B10: expand | C10: 1 | D10: 1 | E10: 1 | F10: 1 | G10: 1 | H10: 1 | I10: 1 | J10: 1 | K10: 1 | L10: 1 | M10: 1,2,4 | R10: expand | S10: 1 | T10: 1 | U10: 1 | V10: 1 | W10: 1 | X10: 1 | Y10: 1 | Z10: 1 | AA10: 1 | AB10: 1 | AC10: 1,2,4
B11: d_conv | C11: 4 | D11: 4 | E11: 4 | F11: 4 | G11: 4 | H11: 4 | I11: 4 | J11: 4 | K11: 4 | L11: 4 | M11: 1,2,4 | R11: d_conv | S11: 4 | T11: 4 | U11: 4 | V11: 4 | W11: 4 | X11: 4 | Y11: 4 | Z11: 4 | AA11: 4 | AB11: 4 | AC11: 1,2,4
B12: # of exp. | C12: 240 | D12: 30 | E12: 240 | F12: 240 | G12: 240 | H12: 240 | I12: 240 | J12: 240 | K12: 30 | L12: 240 | M12: 270 | R12: \# of exp. | S12: 240 | T12: 30 | U12: 240 | V12: 240 | W12: 240 | X12: 240 | Y12: 240 | Z12: 240 | AA12: 30 | AB12: 240 | AC12: 270
B13: EC | C13: 33.079848 | D13: 32.319392 | E13: 39.543726 | F13: 34.60076 | G13: 32.69962 | H13: 41.825095 | I13: 33.079848 | J13: 42.585551 | K13: 30.418251 | L13: 34.220532 | M13: 33.460076 | R13: EthanolConcentration | S13: 33.079848 | T13: 32.319392 | U13: 39.543726 | V13: 34.60076 | W13: 32.69962 | X13: 41.825095 | Y13: 33.079848 | Z13: 42.585551 | AA13: 30.418251 | AB13: 34.220532 | AC13: 33.460076
B14: FD | C14: 69.296254 | D14: 68.586833 | E14: 69.211124 | F14: 70.005675 | G14: 70.034052 | H14: 69.012486 | I14: 66.827469 | J14: 69.296254 | K14: 68.785471 | L14: 69.15437 | M14: 69.494892 | R14: FaceDetection | S14: 69.296254 | T14: 68.586833 | U14: 69.211124 | V14: 70.005675 | W14: 70.034052 | X14: 69.012486 | Y14: 66.827469 | Z14: 69.296254 | AA14: 68.785471 | AB14: 69.15437 | AC14: 69.494892
B15: HW | C15: 60.235294 | D15: 54 | E15: 58 | F15: 47.294118 | G15: 59.882353 | H15: 45.529412 | I15: 56.705882 | J15: 60.823529 | K15: 30.941176 | L15: 60.470588 | M15: 56 | R15: Handwriting | S15: 60.235294 | T15: 54 | U15: 58 | V15: 47.294118 | W15: 59.882353 | X15: 45.529412 | Y15: 56.705882 | Z15: 60.823529 | AA15: 30.941176 | AB15: 60.470588 | AC15: 56
B16: HB | C16: 80.97561 | D16: 79.02439 | E16: 80 | F16: 80 | G16: 80.487805 | H16: 80.97561 | I16: 78.536585 | J16: 80.487805 | K16: 77.073171 | L16: 80.97561 | M16: 80.97561 | R16: Heartbeat | S16: 80.97561 | T16: 79.02439 | U16: 80 | V16: 80 | W16: 80.487805 | X16: 80.97561 | Y16: 78.536585 | Z16: 80 | AA16: 77.073171 | AB16: 80.97561 | AC16: 80.97561
B17: JV | C17: 98.648649 | D17: 98.108108 | E17: 98.648649 | F17: 98.648649 | G17: 98.108108 | H17: 98.918919 | I17: 98.918919 | J17: 98.648649 | K17: 97.297297 | L17: 97.837838 | M17: 98.918919 | R17: JapaneseVowels | S17: 98.648649 | T17: 98.108108 | U17: 98.648649 | V17: 98.648649 | W17: 98.108108 | X17: 98.918919 | Y17: 98.918919 | Z17: 98.648649 | AA17: 97.297297 | AB17: 97.837838 | AC17: 98.918919
B18: PEMS | C18: 85.549133 | D18: 82.65896 | E18: 87.283237 | F18: 90.751445 | G18: 82.65896 | H18: 85.549133 | I18: 89.595376 | J18: 85.549133 | K18: 93.063584 | L18: 83.815029 | M18: 85.549133 | R18: PEMS-SF | S18: 85.549133 | T18: 82.65896 | U18: 87.283237 | V18: 90.751445 | W18: 82.65896 | X18: 85.549133 | Y18: 89.595376 | Z18: 85.549133 | AA18: 93.063584 | AB18: 83.815029 | AC18: 85.549133
B19: SRS1 | C19: 92.150171 | D19: 89.761092 | E19: 91.808874 | F19: 93.174061 | G19: 91.467577 | H19: 90.102389 | I19: 87.713311 | J19: 92.491468 | K19: 92.832765 | L19: 91.12628 | M19: 91.808874 | R19: SelfRegulationSCP1 | S19: 92.150171 | T19: 89.761092 | U19: 91.808874 | V19: 93.174061 | W19: 91.467577 | X19: 90.102389 | Y19: 87.713311 | Z19: 92.491468 | AA19: 92.832765 | AB19: 91.12628 | AC19: 91.808874
B20: SRS2 | C20: 61.111111 | D20: 61.111111 | E20: 60.555556 | F20: 61.111111 | G20: 60 | H20: 63.333333 | I20: 61.111111 | J20: 65 | K20: 58.888889 | L20: 60.555556 | M20: 62.222222 | R20: SelfRegulationSCP2 | S20: 61.111111 | T20: 61.111111 | U20: 60.555556 | V20: 61.111111 | W20: 60 | X20: 63.333333 | Y20: 61.111111 | Z20: 65 | AA20: 58.888889 | AB20: 60.555556 | AC20: 62.222222
B21: SAD | C21: 99.954525 | D21: 99.772624 | E21: 99.90905 | F21: 99.727149 | G21: 99.90905 | H21: 99.863574 | I21: 99.818099 | J21: 99.954525 | K21: 99.181446 | L21: 99.954525 | M21: 99.818099 | R21: SpokenArabicDigits | S21: 99.954525 | T21: 99.772624 | U21: 99.90905 | V21: 99.727149 | W21: 99.90905 | X21: 99.863574 | Y21: 99.818099 | Z21: 99.954525 | AA21: 99.181446 | AB21: 99.954525 | AC21: 99.818099
B22: UW | C22: 93.125 | D22: 91.25 | E22: 92.1875 | F22: 89.0625 | G22: 93.75 | H22: 89.375 | I22: 86.25 | J22: 93.4375 | K22: 84.375 | L22: 92.8125 | M22: 93.4375 | R22: UWaveGestureLibrary | S22: 93.125 | T22: 91.25 | U22: 92.1875 | V22: 89.0625 | W22: 93.75 | X22: 89.375 | Y22: 86.25 | Z22: 93.4375 | AA22: 84.375 | AB22: 92.8125 | AC22: 93.4375
B23: AWR | C23: 99.333333 | D23: 99.333333 | E23: 99 | F23: 99 | G23: 99.333333 | H23: 99 | I23: 97 | J23: 99.333333 | K23: 97.666667 | L23: 99 | M23: 99.333333 | R23: ArticularyWordRecognition | S23: 99.333333 | T23: 99.333333 | U23: 99 | V23: 99 | W23: 99.333333 | X23: 99 | Y23: 97 | Z23: 99.333333 | AA23: 97.666667 | AB23: 99 | AC23: 99.333333
... B42: SWJ | C42: 80 | D42: 60 | E42: 66.666667 | F42: 73.333333 | G42: 66.666667 | H42: 66.666667 | I42: 66.666667 | J42: 73.333333 | K42: 73.333333 | L42: 53.333333 | M42: 73.333333 | R42: StandWalkJump | S42: 80 | T42: 60 | U42: 66.666667 | V42: 73.333333 | W42: 66.666667 | X42: 66.666667 | Y42: 66.666667 | Z42: 73.333333 | AA42: 73.333333 | AB42: 53.333333 | AC42: 73.333333
B43: avg. accuracy (10) | C43: =AVERAGE(C13:C22) -> 77.412559 | D43: =AVERAGE(D13:D22) -> 75.659251 | E43: =AVERAGE(E13:E22) -> 77.714771 | F43: =AVERAGE(F13:F22) -> 76.437547 | G43: =AVERAGE(G13:G22) -> 76.899752 | H43: =AVERAGE(H13:H22) -> 76.448495 | I43: =AVERAGE(I13:I22) -> 75.85566 | J43: =AVERAGE(J13:J22) -> 78.827441 | K43: 73.285705 | L43: 77.092283 | M43: 77.168532 | R43: avg. accuracy (10) | S43: 77.412559 | T43: 75.659251 | U43: 77.714771 | V43: 76.437547 | W43: 76.899752 | X43: 76.448495 | Y43: 75.85566 | Z43: 78.778661 | AA43: 73.285705 | AB43: 77.092283 | AC43: 77.168532
B44: avg. accuracy (all) | C44: =AVERAGE(C13:C42) -> 80.214932 | D44: =AVERAGE(D13:D42) -> 77.075214 | E44: =AVERAGE(E13:E42) -> 79.162988 | F44: =AVERAGE(F13:F42) -> 77.722172 | G44: =AVERAGE(G13:G42) -> 78.60967 | H44: =AVERAGE(H13:H42) -> 78.535223 | I44: =AVERAGE(I13:I42) -> 76.848214 | J44: =AVERAGE(J13:J42) -> 79.818525 | K44: 74.242717 | L44: 77.93505 | M44: 79.348391 | R44: avg. accuracy (all) | S44: 80.214932 | T44: 77.075214 | U44: 79.162988 | V44: 77.722172 | W44: 78.60967 | X44: 78.535223 | Y44: 76.848214 | Z44: 79.802265 | AA44: 74.242717 | AB44: 77.93505 | AC44: 79.348391
B45: avg. rank | C45: =C80 -> 2.5333333 | D45: =D80 -> 5.9333333 | E45: =E80 -> 3.5333333 | F45: =F80 -> 4.9 | G45: =G80 -> 3.6 | H45: =H80 -> 3.9 | I45: =I80 -> 4.8666667 | J45: =J80 -> 2.4 | K45: . | L45: . | M45: . | R45: avg. rank | S45: 2.5333333 | T45: 5.9333333 | U45: 3.5 | V45: 4.8666667 | W45: 3.6 | X45: 3.9 | Y45: 4.8666667 | Z45: 2.4333333 | AA45: . | AB45: . | AC45: .
B46: # of win/draw | C46: {=SUM(--($J13:$J42>=C13:C42))} -> 25 | D46: {=SUM(--($J13:$J42>=D13:D42))} -> 30 | E46: {=SUM(--($J13:$J42>=E13:E42))} -> 22 | F46: {=SUM(--($J13:$J42>=F13:F42))} -> 24 | G46: {=SUM(--($J13:$J42>=G13:G42))} -> 23 | H46: {=SUM(--($J13:$J42>=H13:H42))} -> 22 | I46: {=SUM(--($J13:$J42>=I13:I42))} -> 25 | J46: . | K46: {=SUM(--($J13:$J42>=K13:K42))} -> 26 | L46: {=SUM(--($J13:$J42>=L13:L42))} -> 20 | M46: {=SUM(--($J13:$J42>=M13:M42))} -> 20 | R46: \# of win/draw | S46: 25 | T46: 30 | U46: 22 | V46: 24 | W46: 22 | X46: 22 | Y46: 25 | Z46: . | AA46: 26 | AB46: 20 | AC46: 20
B47: # of lose/draw | C47: {=SUM(--($J13:$J42<=C13:C42))} -> 22 | D47: {=SUM(--($J13:$J42<=D13:D42))} -> 5 | E47: {=SUM(--($J13:$J42<=E13:E42))} -> 13 | F47: {=SUM(--($J13:$J42<=F13:F42))} -> 9 | G47: {=SUM(--($J13:$J42<=G13:G42))} -> 15 | H47: {=SUM(--($J13:$J42<=H13:H42))} -> 12 | I47: {=SUM(--($J13:$J42<=I13:I42))} -> 9 | J47: . | K47: {=SUM(--($J13:$J42<=K13:K42))} -> 5 | L47: {=SUM(--($J13:$J42<=L13:L42))} -> 13 | M47: {=SUM(--($J13:$J42<=M13:M42))} -> 17 | R47: \# of lose/draw | S47: 22 | T47: 5 | U47: 14 | V47: 10 | W47: 15 | X47: 12 | Y47: 9 | Z47: . | AA47: 5 | AB47: 13 | AC47: 17
C50: =RANK(C13,$C13:$J13) -> 5 | D50: =RANK(D13,$C13:$J13) -> 8 | E50: =RANK(E13,$C13:$J13) -> 3 | F50: =RANK(F13,$C13:$J13) -> 4 | G50: =RANK(G13,$C13:$J13) -> 7 | H50: =RANK(H13,$C13:$J13) -> 2 | I50: =RANK(I13,$C13:$J13) -> 5 | J50: =RANK(J13,$C13:$J13) -> 1
C51: =RANK(C14,$C14:$J14) -> 3 | D51: =RANK(D14,$C14:$J14) -> 7 | E51: =RANK(E14,$C14:$J14) -> 5 | F51: =RANK(F14,$C14:$J14) -> 2 | G51: =RANK(G14,$C14:$J14) -> 1 | H51: =RANK(H14,$C14:$J14) -> 6 | I51: =RANK(I14,$C14:$J14) -> 8 | J51: =RANK(J14,$C14:$J14) -> 4
C52: =RANK(C15,$C15:$J15) -> 2 | D52: =RANK(D15,$C15:$J15) -> 6 | E52: =RANK(E15,$C15:$J15) -> 4 | F52: =RANK(F15,$C15:$J15) -> 7 | G52: =RANK(G15,$C15:$J15) -> 3 | H52: =RANK(H15,$C15:$J15) -> 8 | I52: =RANK(I15,$C15:$J15) -> 5 | J52: =RANK(J15,$C15:$J15) -> 1
C53: =RANK(C16,$C16:$J16) -> 1 | D53: =RANK(D16,$C16:$J16) -> 7 | E53: =RANK(E16,$C16:$J16) -> 5 | F53: =RANK(F16,$C16:$J16) -> 5 | G53: =RANK(G16,$C16:$J16) -> 3 | H53: =RANK(H16,$C16:$J16) -> 1 | I53: =RANK(I16,$C16:$J16) -> 8 | J53: =RANK(J16,$C16:$J16) -> 3
C54: =RANK(C17,$C17:$J17) -> 3 | D54: =RANK(D17,$C17:$J17) -> 7 | E54: =RANK(E17,$C17:$J17) -> 3 | F54: =RANK(F17,$C17:$J17) -> 3 | G54: =RANK(G17,$C17:$J17) -> 7 | H54: =RANK(H17,$C17:$J17) -> 1 | I54: =RANK(I17,$C17:$J17) -> 1 | J54: =RANK(J17,$C17:$J17) -> 3
C55: =RANK(C18,$C18:$J18) -> 4 | D55: =RANK(D18,$C18:$J18) -> 7 | E55: =RANK(E18,$C18:$J18) -> 3 | F55: =RANK(F18,$C18:$J18) -> 1 | G55: =RANK(G18,$C18:$J18) -> 8 | H55: =RANK(H18,$C18:$J18) -> 4 | I55: =RANK(I18,$C18:$J18) -> 2 | J55: =RANK(J18,$C18:$J18) -> 4
C56: =RANK(C19,$C19:$J19) -> 3 | D56: =RANK(D19,$C19:$J19) -> 7 | E56: =RANK(E19,$C19:$J19) -> 4 | F56: =RANK(F19,$C19:$J19) -> 1 | G56: =RANK(G19,$C19:$J19) -> 5 | H56: =RANK(H19,$C19:$J19) -> 6 | I56: =RANK(I19,$C19:$J19) -> 8 | J56: =RANK(J19,$C19:$J19) -> 2
C57: =RANK(C20,$C20:$J20) -> 3 | D57: =RANK(D20,$C20:$J20) -> 6 | E57: =RANK(E20,$C20:$J20) -> 7 | F57: =RANK(F20,$C20:$J20) -> 3 | G57: =RANK(G20,$C20:$J20) -> 8 | H57: =RANK(H20,$C20:$J20) -> 2 | I57: =RANK(I20,$C20:$J20) -> 3 | J57: =RANK(J20,$C20:$J20) -> 1
C58: =RANK(C21,$C21:$J21) -> 2 | D58: =RANK(D21,$C21:$J21) -> 7 | E58: =RANK(E21,$C21:$J21) -> 3 | F58: =RANK(F21,$C21:$J21) -> 8 | G58: =RANK(G21,$C21:$J21) -> 3 | H58: =RANK(H21,$C21:$J21) -> 5 | I58: =RANK(I21,$C21:$J21) -> 6 | J58: =RANK(J21,$C21:$J21) -> 1
C59: =RANK(C22,$C22:$J22) -> 3 | D59: =RANK(D22,$C22:$J22) -> 5 | E59: =RANK(E22,$C22:$J22) -> 4 | F59: =RANK(F22,$C22:$J22) -> 7 | G59: =RANK(G22,$C22:$J22) -> 1 | H59: =RANK(H22,$C22:$J22) -> 6 | I59: =RANK(I22,$C22:$J22) -> 8 | J59: =RANK(J22,$C22:$J22) -> 2
C60: =RANK(C23,$C23:$J23) -> 1 | D60: =RANK(D23,$C23:$J23) -> 4 | E60: =RANK(E23,$C23:$J23) -> 5 | F60: =RANK(F23,$C23:$J23) -> 5 | G60: =RANK(G23,$C23:$J23) -> 1 | H60: =RANK(H23,$C23:$J23) -> 5 | I60: =RANK(I23,$C23:$J23) -> 8 | J60: =RANK(J23,$C23:$J23) -> 1
C61: =RANK(C24,$C24:$J24) -> 1 | D61: =RANK(D24,$C24:$J24) -> 8 | E61: =RANK(E24,$C24:$J24) -> 5 | F61: =RANK(F24,$C24:$J24) -> 2 | G61: =RANK(G24,$C24:$J24) -> 5 | H61: =RANK(H24,$C24:$J24) -> 2 | I61: =RANK(I24,$C24:$J24) -> 2 | J61: =RANK(J24,$C24:$J24) -> 5
...
