Workbook

Sheet UEA30 (colored)
B4: non-DL | G4: MLP-based | J4: CNN-based | L4: CNN-based | N4: Transformer-based | T4: shape-based | U4: Mamba-based
A5: Dataset | B5: DTW_D | C5: ROCKET | D5: HC2 | E5: Hydra | F5: MR+Hydra | G5: Dlinear | H5: LightTS | I5: MTS-Mixer | J5: TimesNet | K5: ModernTCN | L5: TSLANet | M5: TimeMixer++ | N5: FEDformer | O5: ETSformer | P5: Crossformer | Q5: PatchTST | R5: GPT4TS | S5: iTransformer | T5: InterpGN | U5: TSCMamba | V5: MambaSL
A6: EC | B6: 32.319392 | C6: 44.486692 | D6: 52.851711 | E6: 54.372624 | F6: 60.076046 | G6: 31.178707 | H6: 32.319392 | I6: 30.798479 | J6: 33.460076 | K6: 32.319392 | L6: 31.939163 | M6: 34.60076 | N6: 33.840304 | O6: 33.079848 | P6: 43.346008 | Q6: 32.69962 | R6: 32.319392 | S6: 31.939163 | T6: 28.897338 | U6: 30.798479 | V6: 42.585551
A7: FD | B7: 52.866061 | C7: 61.606129 | D7: 61.379115 | E7: 60.981839 | F7: 61.293984 | G7: 69.494892 | H7: 68.473326 | I7: 68.530079 | J7: 70.14756 | K7: 66.99773 | L7: 66.969353 | M7: 69.665153 | N7: 69.892168 | O7: 68.331442 | P7: 69.636776 | Q7: 68.07605 | R7: 68.61521 | S7: 68.416572 | T7: 63.791146 | U7: 70.204313 | V7: 69.296254
A8: HW | B8: 60.705882 | C8: 59.294118 | D8: 56 | E8: 56.352941 | F8: 53.529412 | G8: 23.764706 | H8: 25.058824 | I8: 19.647059 | J8: 37.529412 | K8: 30.117647 | L8: 62 | M8: 33.647059 | N8: 33.411765 | O8: 35.647059 | P8: 30.352941 | Q8: 29.529412 | R8: 34.117647 | S8: 31.294118 | T8: 58.705882 | U8: 45.058824 | V8: 60.823529
A9: HB | B9: 71.707317 | C9: 75.609756 | D9: 78.536585 | E9: 76.585366 | F9: 77.073171 | G9: 76.585366 | H9: 77.560976 | I9: 79.02439 | J9: 83.902439 | K9: 78.04878 | L9: 79.512195 | M9: 80.487805 | N9: 78.04878 | O9: 78.536585 | P9: 79.02439 | Q9: 73.658537 | R9: 79.02439 | S9: 78.04878 | T9: 80.487805 | U9: 78.536585 | V9: 80
A10: JV | B10: 95.945946 | C10: 83.783784 | D10: 98.378378 | E10: 97.837838 | F10: 98.378378 | G10: 96.486486 | H10: 96.756757 | I10: 95.945946 | J10: 98.648649 | K10: 98.648649 | L10: 98.918919 | M10: 99.189189 | N10: 97.567568 | O10: 98.378378 | P10: 98.378378 | Q10: 97.027027 | R10: 98.108108 | S10: 98.108108 | T10: 99.72973 | U10: 98.378378 | V10: 98.648649
A11: PEMS | B11: 71.098266 | C11: 84.393064 | D11: 97.687861 | E11: 98.265896 | F11: 82.65896 | G11: 82.65896 | H11: 87.861272 | I11: 82.080925 | J11: 87.861272 | K11: 86.705202 | L11: 89.017341 | M11: 89.017341 | N11: 89.017341 | O11: 87.861272 | P11: 89.595376 | Q11: 89.017341 | R11: 88.439306 | S11: 91.32948 | T11: 86.127168 | U11: 90.17341 | V11: 85.549133
A12: SRS1 | B12: 77.474403 | C12: 85.665529 | D12: 89.078498 | E12: 86.68942 | F12: 94.880546 | G12: 92.832765 | H12: 92.832765 | I12: 78.83959 | J12: 92.150171 | K12: 93.515358 | L12: 89.761092 | M12: 92.150171 | N12: 75.085324 | O12: 92.150171 | P12: 93.856655 | Q12: 89.078498 | R12: 93.174061 | S12: 93.856655 | T12: 90.443686 | U12: 92.832765 | V12: 92.491468
A13: SRS2 | B13: 53.888889 | C13: 55.555556 | D13: 54.444444 | E13: 58.888889 | F13: 55 | G13: 57.222222 | H13: 59.444444 | I13: 58.333333 | J13: 60 | K13: 60 | L13: 63.888889 | M13: 60.555556 | N13: 59.444444 | O13: 60 | P13: 61.666667 | Q13: 61.666667 | R13: 60.555556 | S13: 58.888889 | T13: 58.333333 | U13: 62.222222 | V13: 65
A14: SAD | B14: 97.226012 | C14: 99.226921 | D14: 99.135971 | E14: 99.135971 | F14: 99.04502 | G14: 96.953161 | H14: 98.226467 | I14: 99.454297 | J14: 99.545248 | K14: 99.499773 | L14: 98.044566 | M14: 99.545248 | N14: 99.454297 | O14: 98.999545 | P14: 98.86312 | Q14: 98.817644 | R14: 99.590723 | S14: 99.317872 | T14: 99.863574 | U14: 95.81628 | V14: 99.954525
A15: UW | B15: 90.3125 | C15: 94.0625 | D15: 94.0625 | E15: 94.375 | F15: 94.0625 | G15: 82.8125 | H15: 89.0625 | I15: 83.125 | J15: 88.4375 | K15: 88.4375 | L15: 94.375 | M15: 90.625 | N15: 79.6875 | O15: 89.6875 | P15: 88.4375 | Q15: 89.375 | R15: 89.0625 | S15: 90 | T15: 88.4375 | U15: 95.3125 | V15: 93.4375
A16: AWR | B16: 98.666667 | C16: 99.333333 | D16: 99.333333 | E16: 99.333333 | F16: 99.333333 | G16: 97.666667 | H16: 98.333333 | I16: 99 | J16: 98.666667 | K16: 98.666667 | L16: 99.333333 | M16: 99 | N16: 92.333333 | O16: 98.666667 | P16: 98.666667 | Q16: 98.666667 | R16: 98.666667 | S16: 99 | T16: 99 | U16: 99.333333 | V16: 99.333333
A17: AF | B17: 20 | C17: 6.6666667 | D17: 20 | E17: 26.666667 | F17: 6.6666667 | G17: 53.333333 | H17: 73.333333 | I17: 60 | J17: 66.666667 | K17: 73.333333 | L17: 66.666667 | M17: 66.666667 | N17: 73.333333 | O17: 80 | P17: 73.333333 | Q17: 80 | R17: 66.666667 | S17: 66.666667 | T17: 46.666667 | U17: 66.666667 | V17: 53.333333
... A35: SWJ | B35: 20 | C35: 46.666667 | D35: 40 | E35: 40 | F35: 66.666667 | G35: 53.333333 | H35: 73.333333 | I35: 66.666667 | J35: 66.666667 | K35: 80 | L35: 73.333333 | M35: 73.333333 | N35: 66.666667 | O35: 66.666667 | P35: 80 | Q35: 86.666667 | R35: 73.333333 | S35: 73.333333 | T35: 60 | U35: 73.333333 | V35: 73.333333
A36: avg. acc (10) | B36: =AVERAGE(B6:B15) -> 70.354467 | C36: =AVERAGE(C6:C15) -> 74.368405 | D36: =AVERAGE(D6:D15) -> 78.155506 | E36: =AVERAGE(E6:E15) -> 78.348578 | F36: =AVERAGE(F6:F15) -> 77.599802 | G36: =AVERAGE(G6:G15) -> 70.998976 | H36: =AVERAGE(H6:H15) -> 72.759672 | I36: =AVERAGE(I6:I15) -> 69.57791 | ... V36: =AVERAGE(V6:V15) -> 78.778661
A37: avg. acc | B37: =AVERAGE(B6:B35) -> 68.019691 | C37: =AVERAGE(C6:C35) -> 73.305689 | D37: =AVERAGE(D6:D35) -> 76.865881 | E37: =AVERAGE(E6:E35) -> 77.124035 | F37: =AVERAGE(F6:F35) -> 76.320338 | G37: =AVERAGE(G6:G35) -> 68.246934 | H37: =AVERAGE(H6:H35) -> 75.307907 | I37: =AVERAGE(I6:I35) -> 69.001332 | ... V37: =AVERAGE(V6:V35) -> 79.802265
A38: avg. rank | B38: =AVERAGE(B50:B79) -> 16.033333 | C38: =AVERAGE(C50:C79) -> 11.2 | D38: =AVERAGE(D50:D79) -> 8.9 | E38: =AVERAGE(E50:E79) -> 8.8333333 | F38: =AVERAGE(F50:F79) -> 9.4 | G38: =AVERAGE(G50:G79) -> 16.8 | H38: =AVERAGE(H50:H79) -> 11.833333 | I38: =AVERAGE(I50:I79) -> 13.9 | ... V38: =AVERAGE(V50:V79) -> 5.3666667
A39: \# of top-1 | B39: =COUNTIF(B50:B79,"1") -> 1 | C39: =COUNTIF(C50:C79,"1") -> 3 | D39: =COUNTIF(D50:D79,"1") -> 4 | E39: =COUNTIF(E50:E79,"1") -> 7 | F39: =COUNTIF(F50:F79,"1") -> 8 | G39: =COUNTIF(G50:G79,"1") -> 0 | H39: =COUNTIF(H50:H79,"1") -> 1 | I39: =COUNTIF(I50:I79,"1") -> 1 | ... V39: =COUNTIF(V50:V79,"1") -> 5
A40: \# of top-5 | B40: =COUNTIF(B50:B79,"<=5") -> 2 | C40: =COUNTIF(C50:C79,"<=5") -> 10 | D40: =COUNTIF(D50:D79,"<=5") -> 13 | E40: =COUNTIF(E50:E79,"<=5") -> 13 | F40: =COUNTIF(F50:F79,"<=5") -> 12 | G40: =COUNTIF(G50:G79,"<=5") -> 0 | H40: =COUNTIF(H50:H79,"<=5") -> 6 | I40: =COUNTIF(I50:I79,"<=5") -> 3 | ... V40: =COUNTIF(V50:V79,"<=5") -> 18
A41: \# of top-10 | B41: =COUNTIF(B50:B79,"<=10") -> 5 | C41: =COUNTIF(C50:C79,"<=10") -> 15 | D41: =COUNTIF(D50:D79,"<=10") -> 19 | E41: =COUNTIF(E50:E79,"<=10") -> 17 | F41: =COUNTIF(F50:F79,"<=10") -> 16 | G41: =COUNTIF(G50:G79,"<=10") -> 5 | H41: =COUNTIF(H50:H79,"<=10") -> 11 | I41: =COUNTIF(I50:I79,"<=10") -> 9 | ... V41: =COUNTIF(V50:V79,"<=10") -> 27
A42: \# of win/draw | B42: {=SUM(--(B6:B35<=$V6:$V35))} -> 29 | C42: {=SUM(--(C6:C35<=$V6:$V35))} -> 24 | D42: {=SUM(--(D6:D35<=$V6:$V35))} -> 20 | E42: {=SUM(--(E6:E35<=$V6:$V35))} -> 20 | F42: {=SUM(--(F6:F35<=$V6:$V35))} -> 21 | G42: {=SUM(--(G6:G35<=$V6:$V35))} -> 28 | H42: {=SUM(--(H6:H35<=$V6:$V35))} -> 25 | I42: {=SUM(--(I6:I35<=$V6:$V35))} -> 28 | ... U42: {=SUM(--(U6:U35<=$V6:$V35))} -> 20
A43: \# of lose/draw | B43: {=SUM(--(B6:B35>=$V6:$V35))} -> 2 | C43: {=SUM(--(C6:C35>=$V6:$V35))} -> 9 | D43: {=SUM(--(D6:D35>=$V6:$V35))} -> 14 | E43: {=SUM(--(E6:E35>=$V6:$V35))} -> 13 | F43: {=SUM(--(F6:F35>=$V6:$V35))} -> 11 | G43: {=SUM(--(G6:G35>=$V6:$V35))} -> 3 | H43: {=SUM(--(H6:H35>=$V6:$V35))} -> 7 | I43: {=SUM(--(I6:I35>=$V6:$V35))} -> 4 | ... U43: {=SUM(--(U6:U35>=$V6:$V35))} -> 15
A44: Wilcoxon test | B44: 3.6148028e-06 | C44: 0.0008239998 | D44: 0.05621403 | E44: 0.033932669 | F44: 0.015259624 | G44: 1.7574815e-06 | H44: 0.00010291886 | I44: 4.9888494e-06 | J44: 0.0041271717 | K44: 0.0011389956 | L44: 0.039730255 | M44: 0.0065308029 | N44: 8.4948726e-05 | O44: 0.00010429515 | P44: 0.0058827128 | Q44: 0.00048768207 | R44: 0.00018848713 | S44: 0.00017503801 | T44: 0.032784897 | U44: 0.041326512 | V44: 1
A50: =A6 -> EC | B50: =RANK(B6,$B6:$V6) -> 12 | C50: =RANK(C6,$B6:$V6) -> 4 | D50: =RANK(D6,$B6:$V6) -> 3 | E50: =RANK(E6,$B6:$V6) -> 2 | F50: =RANK(F6,$B6:$V6) -> 1 | G50: =RANK(G6,$B6:$V6) -> 18 | H50: =RANK(H6,$B6:$V6) -> 12 | I50: =RANK(I6,$B6:$V6) -> 19 | ... V50: =RANK(V6,$B6:$V6) -> 6
A51: =A7 -> FD | B51: =RANK(B7,$B7:$V7) -> 21 | C51: =RANK(C7,$B7:$V7) -> 17 | D51: =RANK(D7,$B7:$V7) -> 18 | E51: =RANK(E7,$B7:$V7) -> 20 | F51: =RANK(F7,$B7:$V7) -> 19 | G51: =RANK(G7,$B7:$V7) -> 6 | H51: =RANK(H7,$B7:$V7) -> 10 | I51: =RANK(I7,$B7:$V7) -> 9 | ... V51: =RANK(V7,$B7:$V7) -> 7
A52: =A8 -> HW | B52: =RANK(B8,$B8:$V8) -> 3 | C52: =RANK(C8,$B8:$V8) -> 4 | D52: =RANK(D8,$B8:$V8) -> 7 | E52: =RANK(E8,$B8:$V8) -> 6 | F52: =RANK(F8,$B8:$V8) -> 8 | G52: =RANK(G8,$B8:$V8) -> 20 | H52: =RANK(H8,$B8:$V8) -> 19 | I52: =RANK(I8,$B8:$V8) -> 21 | ... V52: =RANK(V8,$B8:$V8) -> 2
A53: =A9 -> HB | B53: =RANK(B9,$B9:$V9) -> 21 | C53: =RANK(C9,$B9:$V9) -> 19 | D53: =RANK(D9,$B9:$V9) -> 9 | E53: =RANK(E9,$B9:$V9) -> 17 | F53: =RANK(F9,$B9:$V9) -> 16 | G53: =RANK(G9,$B9:$V9) -> 17 | H53: =RANK(H9,$B9:$V9) -> 15 | I53: =RANK(I9,$B9:$V9) -> 6 | ... V53: =RANK(V9,$B9:$V9) -> 4
A54: =A10 -> JV | B54: =RANK(B10,$B10:$V10) -> 19 | C54: =RANK(C10,$B10:$V10) -> 21 | D54: =RANK(D10,$B10:$V10) -> 7 | E54: =RANK(E10,$B10:$V10) -> 14 | F54: =RANK(F10,$B10:$V10) -> 7 | G54: =RANK(G10,$B10:$V10) -> 18 | H54: =RANK(H10,$B10:$V10) -> 17 | I54: =RANK(I10,$B10:$V10) -> 19 | ... V54: =RANK(V10,$B10:$V10) -> 4
A55: =A11 -> PEMS | B55: =RANK(B11,$B11:$V11) -> 21 | C55: =RANK(C11,$B11:$V11) -> 17 | D55: =RANK(D11,$B11:$V11) -> 2 | E55: =RANK(E11,$B11:$V11) -> 1 | F55: =RANK(F11,$B11:$V11) -> 18 | G55: =RANK(G11,$B11:$V11) -> 18 | H55: =RANK(H11,$B11:$V11) -> 11 | I55: =RANK(I11,$B11:$V11) -> 20 | ... V55: =RANK(V11,$B11:$V11) -> 16
A56: =A12 -> SRS1 | B56: =RANK(B12,$B12:$V12) -> 20 | C56: =RANK(C12,$B12:$V12) -> 18 | D56: =RANK(D12,$B12:$V12) -> 15 | E56: =RANK(E12,$B12:$V12) -> 17 | F56: =RANK(F12,$B12:$V12) -> 1 | G56: =RANK(G12,$B12:$V12) -> 6 | H56: =RANK(H12,$B12:$V12) -> 6 | I56: =RANK(I12,$B12:$V12) -> 19 | ... V56: =RANK(V12,$B12:$V12) -> 9
A57: =A13 -> SRS2 | B57: =RANK(B13,$B13:$V13) -> 21 | C57: =RANK(C13,$B13:$V13) -> 18 | D57: =RANK(D13,$B13:$V13) -> 20 | E57: =RANK(E13,$B13:$V13) -> 13 | F57: =RANK(F13,$B13:$V13) -> 19 | G57: =RANK(G13,$B13:$V13) -> 17 | H57: =RANK(H13,$B13:$V13) -> 11 | I57: =RANK(I13,$B13:$V13) -> 15 | ... V57: =RANK(V13,$B13:$V13) -> 1
A58: =A14 -> SAD | B58: =RANK(B14,$B14:$V14) -> 19 | C58: =RANK(C14,$B14:$V14) -> 10 | D58: =RANK(D14,$B14:$V14) -> 11 | E58: =RANK(E14,$B14:$V14) -> 11 | F58: =RANK(F14,$B14:$V14) -> 13 | G58: =RANK(G14,$B14:$V14) -> 20 | H58: =RANK(H14,$B14:$V14) -> 17 | I58: =RANK(I14,$B14:$V14) -> 7 | ... V58: =RANK(V14,$B14:$V14) -> 1
A59: =A15 -> UW | B59: =RANK(B15,$B15:$V15) -> 9 | C59: =RANK(C15,$B15:$V15) -> 4 | D59: =RANK(D15,$B15:$V15) -> 4 | E59: =RANK(E15,$B15:$V15) -> 2 | F59: =RANK(F15,$B15:$V15) -> 4 | G59: =RANK(G15,$B15:$V15) -> 20 | H59: =RANK(H15,$B15:$V15) -> 13 | I59: =RANK(I15,$B15:$V15) -> 19 | ... V59: =RANK(V15,$B15:$V15) -> 7
A60: =A16 -> AWR | B60: =RANK(B16,$B16:$V16) -> 12 | C60: =RANK(C16,$B16:$V16) -> 1 | D60: =RANK(D16,$B16:$V16) -> 1 | E60: =RANK(E16,$B16:$V16) -> 1 | F60: =RANK(F16,$B16:$V16) -> 1 | G60: =RANK(G16,$B16:$V16) -> 20 | H60: =RANK(H16,$B16:$V16) -> 19 | I60: =RANK(I16,$B16:$V16) -> 8 | ... V60: =RANK(V16,$B16:$V16) -> 1
A61: =A17 -> AF | B61: =RANK(B17,$B17:$V17) -> 18 | C61: =RANK(C17,$B17:$V17) -> 20 | D61: =RANK(D17,$B17:$V17) -> 18 | E61: =RANK(E17,$B17:$V17) -> 17 | F61: =RANK(F17,$B17:$V17) -> 20 | G61: =RANK(G17,$B17:$V17) -> 14 | H61: =RANK(H17,$B17:$V17) -> 3 | I61: =RANK(I17,$B17:$V17) -> 13 | ... V61: =RANK(V17,$B17:$V17) -> 14
... A81: =A37 -> avg. acc | B81: =RANK(B37,$B37:$V37) -> 21 | C81: =RANK(C37,$B37:$V37) -> 18 | D81: =RANK(D37,$B37:$V37) -> 9 | E81: =RANK(E37,$B37:$V37) -> 6 | F81: =RANK(F37,$B37:$V37) -> 10 | G81: =RANK(G37,$B37:$V37) -> 20 | H81: =RANK(H37,$B37:$V37) -> 14 | I81: =RANK(I37,$B37:$V37) -> 19 | ... V81: =RANK(V37,$B37:$V37) -> 1
A82: =A38 -> avg. rank | B82: =RANK(B38,$B38:$V38,1) -> 20 | C82: =RANK(C38,$B38:$V38,1) -> 14 | D82: =RANK(D38,$B38:$V38,1) -> 9 | E82: =RANK(E38,$B38:$V38,1) -> 8 | F82: =RANK(F38,$B38:$V38,1) -> 11 | G82: =RANK(G38,$B38:$V38,1) -> 21 | H82: =RANK(H38,$B38:$V38,1) -> 15 | I82: =RANK(I38,$B38:$V38,1) -> 19 | ... V82: =RANK(V38,$B38:$V38,1) -> 1
A83: =A39 -> \# of top-1 | B83: =RANK(B39,$B39:$V39) -> 14 | C83: =RANK(C39,$B39:$V39) -> 8 | D83: =RANK(D39,$B39:$V39) -> 7 | E83: =RANK(E39,$B39:$V39) -> 2 | F83: =RANK(F39,$B39:$V39) -> 1 | G83: =RANK(G39,$B39:$V39) -> 20 | H83: =RANK(H39,$B39:$V39) -> 14 | I83: =RANK(I39,$B39:$V39) -> 14 | ... V83: =RANK(V39,$B39:$V39) -> 5
A84: =A40 -> \# of top-5 | B84: =RANK(B40,$B40:$V40) -> 19 | C84: =RANK(C40,$B40:$V40) -> 10 | D84: =RANK(D40,$B40:$V40) -> 4 | E84: =RANK(E40,$B40:$V40) -> 4 | F84: =RANK(F40,$B40:$V40) -> 6 | G84: =RANK(G40,$B40:$V40) -> 21 | H84: =RANK(H40,$B40:$V40) -> 13 | I84: =RANK(I40,$B40:$V40) -> 18 | ... V84: =RANK(V40,$B40:$V40) -> 1
...

Sheet UEA30
B4: non-DL | G4: MLP-based | J4: CNN-based | L4: CNN-based | N4: Transformer-based | T4: shape-based | U4: Mamba-based
A5: Dataset | B5: DTW_D \citeyearpar{} | C5: ROCKET \citeyearpar{} | D5: HC2 \citeyearpar{} | E5: Hydra \citeyearpar{} | F5: MR+Hydra \citeyearpar{} | G5: Dlinear \citeyearpar{} | H5: LightTS \citeyearpar{} | I5: MTS-Mixer \citeyearpar{} | J5: TimesNet \citeyearpar{} | K5: ModernTCN \citeyearpar{} | L5: TSLANet \citeyearpar{} | M5: TimeMixer++ \citeyearpar{} | N5: FEDformer \citeyearpar{} | O5: ETSformer \citeyearpar{} | P5: Crossformer \citeyearpar{} | Q5: PatchTST \citeyearpar{} | R5: GPT4TS \citeyearpar{} | S5: iTransformer \citeyearpar{} | T5: InterpGN \citeyearpar{} | U5: TSCMamba \citeyearpar{} | V5: MambaSL \citeyearpar{}
A6: EC | B6: ='UEA30 (colored)'!B6 -> 32.319392 | C6: ='UEA30 (colored)'!C6 -> 44.486692 | D6: ='UEA30 (colored)'!D6 -> 52.851711 | E6: ='UEA30 (colored)'!E6 -> 54.372624 | F6: ='UEA30 (colored)'!F6 -> 60.076046 | G6: ='UEA30 (colored)'!G6 -> 31.178707 | H6: ='UEA30 (colored)'!H6 -> 32.319392 | I6: ='UEA30 (colored)'!I6 -> 30.798479 | ... V6: ='UEA30 (colored)'!V6 -> 42.585551
A7: FD | B7: ='UEA30 (colored)'!B7 -> 52.866061 | C7: ='UEA30 (colored)'!C7 -> 61.606129 | D7: ='UEA30 (colored)'!D7 -> 61.379115 | E7: ='UEA30 (colored)'!E7 -> 60.981839 | F7: ='UEA30 (colored)'!F7 -> 61.293984 | G7: ='UEA30 (colored)'!G7 -> 69.494892 | H7: ='UEA30 (colored)'!H7 -> 68.473326 | I7: ='UEA30 (colored)'!I7 -> 68.530079 | ... V7: ='UEA30 (colored)'!V7 -> 69.296254
A8: HW | B8: ='UEA30 (colored)'!B8 -> 60.705882 | C8: ='UEA30 (colored)'!C8 -> 59.294118 | D8: ='UEA30 (colored)'!D8 -> 56 | E8: ='UEA30 (colored)'!E8 -> 56.352941 | F8: ='UEA30 (colored)'!F8 -> 53.529412 | G8: ='UEA30 (colored)'!G8 -> 23.764706 | H8: ='UEA30 (colored)'!H8 -> 25.058824 | I8: ='UEA30 (colored)'!I8 -> 19.647059 | ... V8: ='UEA30 (colored)'!V8 -> 60.823529
A9: HB | B9: ='UEA30 (colored)'!B9 -> 71.707317 | C9: ='UEA30 (colored)'!C9 -> 75.609756 | D9: ='UEA30 (colored)'!D9 -> 78.536585 | E9: ='UEA30 (colored)'!E9 -> 76.585366 | F9: ='UEA30 (colored)'!F9 -> 77.073171 | G9: ='UEA30 (colored)'!G9 -> 76.585366 | H9: ='UEA30 (colored)'!H9 -> 77.560976 | I9: ='UEA30 (colored)'!I9 -> 79.02439 | ... V9: ='UEA30 (colored)'!V9 -> 80
A10: JV | B10: ='UEA30 (colored)'!B10 -> 95.945946 | C10: ='UEA30 (colored)'!C10 -> 83.783784 | D10: ='UEA30 (colored)'!D10 -> 98.378378 | E10: ='UEA30 (colored)'!E10 -> 97.837838 | F10: ='UEA30 (colored)'!F10 -> 98.378378 | G10: ='UEA30 (colored)'!G10 -> 96.486486 | H10: ='UEA30 (colored)'!H10 -> 96.756757 | I10: ='UEA30 (colored)'!I10 -> 95.945946 | ... V10: ='UEA30 (colored)'!V10 -> 98.648649
A11: PEMS | B11: ='UEA30 (colored)'!B11 -> 71.098266 | C11: ='UEA30 (colored)'!C11 -> 84.393064 | D11: ='UEA30 (colored)'!D11 -> 97.687861 | E11: ='UEA30 (colored)'!E11 -> 98.265896 | F11: ='UEA30 (colored)'!F11 -> 82.65896 | G11: ='UEA30 (colored)'!G11 -> 82.65896 | H11: ='UEA30 (colored)'!H11 -> 87.861272 | I11: ='UEA30 (colored)'!I11 -> 82.080925 | ... V11: ='UEA30 (colored)'!V11 -> 85.549133
A12: SRS1 | B12: ='UEA30 (colored)'!B12 -> 77.474403 | C12: ='UEA30 (colored)'!C12 -> 85.665529 | D12: ='UEA30 (colored)'!D12 -> 89.078498 | E12: ='UEA30 (colored)'!E12 -> 86.68942 | F12: ='UEA30 (colored)'!F12 -> 94.880546 | G12: ='UEA30 (colored)'!G12 -> 92.832765 | H12: ='UEA30 (colored)'!H12 -> 92.832765 | I12: ='UEA30 (colored)'!I12 -> 78.83959 | ... V12: ='UEA30 (colored)'!V12 -> 92.491468
A13: SRS2 | B13: ='UEA30 (colored)'!B13 -> 53.888889 | C13: ='UEA30 (colored)'!C13 -> 55.555556 | D13: ='UEA30 (colored)'!D13 -> 54.444444 | E13: ='UEA30 (colored)'!E13 -> 58.888889 | F13: ='UEA30 (colored)'!F13 -> 55 | G13: ='UEA30 (colored)'!G13 -> 57.222222 | H13: ='UEA30 (colored)'!H13 -> 59.444444 | I13: ='UEA30 (colored)'!I13 -> 58.333333 | ... V13: ='UEA30 (colored)'!V13 -> 65
A14: SAD | B14: ='UEA30 (colored)'!B14 -> 97.226012 | C14: ='UEA30 (colored)'!C14 -> 99.226921 | D14: ='UEA30 (colored)'!D14 -> 99.135971 | E14: ='UEA30 (colored)'!E14 -> 99.135971 | F14: ='UEA30 (colored)'!F14 -> 99.04502 | G14: ='UEA30 (colored)'!G14 -> 96.953161 | H14: ='UEA30 (colored)'!H14 -> 98.226467 | I14: ='UEA30 (colored)'!I14 -> 99.454297 | ... V14: ='UEA30 (colored)'!V14 -> 99.954525
A15: UW | B15: ='UEA30 (colored)'!B15 -> 90.3125 | C15: ='UEA30 (colored)'!C15 -> 94.0625 | D15: ='UEA30 (colored)'!D15 -> 94.0625 | E15: ='UEA30 (colored)'!E15 -> 94.375 | F15: ='UEA30 (colored)'!F15 -> 94.0625 | G15: ='UEA30 (colored)'!G15 -> 82.8125 | H15: ='UEA30 (colored)'!H15 -> 89.0625 | I15: ='UEA30 (colored)'!I15 -> 83.125 | ... V15: ='UEA30 (colored)'!V15 -> 93.4375
A16: AWR | B16: ='UEA30 (colored)'!B16 -> 98.666667 | C16: ='UEA30 (colored)'!C16 -> 99.333333 | D16: ='UEA30 (colored)'!D16 -> 99.333333 | E16: ='UEA30 (colored)'!E16 -> 99.333333 | F16: ='UEA30 (colored)'!F16 -> 99.333333 | G16: ='UEA30 (colored)'!G16 -> 97.666667 | H16: ='UEA30 (colored)'!H16 -> 98.333333 | I16: ='UEA30 (colored)'!I16 -> 99 | ... V16: ='UEA30 (colored)'!V16 -> 99.333333
A17: AF | B17: ='UEA30 (colored)'!B17 -> 20 | C17: ='UEA30 (colored)'!C17 -> 6.6666667 | D17: ='UEA30 (colored)'!D17 -> 20 | E17: ='UEA30 (colored)'!E17 -> 26.666667 | F17: ='UEA30 (colored)'!F17 -> 6.6666667 | G17: ='UEA30 (colored)'!G17 -> 53.333333 | H17: ='UEA30 (colored)'!H17 -> 73.333333 | I17: ='UEA30 (colored)'!I17 -> 60 | ... V17: ='UEA30 (colored)'!V17 -> 53.333333
... A44: Wilcoxon test | B44: ='UEA30 (colored)'!B44 -> 3.6148028e-06 | C44: ='UEA30 (colored)'!C44 -> 0.0008239998 | D44: ='UEA30 (colored)'!D44 -> 0.05621403 | E44: ='UEA30 (colored)'!E44 -> 0.033932669 | F44: ='UEA30 (colored)'!F44 -> 0.015259624 | G44: ='UEA30 (colored)'!G44 -> 1.7574815e-06 | H44: ='UEA30 (colored)'!H44 -> 0.00010291886 | I44: ='UEA30 (colored)'!I44 -> 4.9888494e-06 | ... V44: ='UEA30 (colored)'!V44 -> 1
A50: =A6 -> EC | B50: =RANK(B6,$B6:$V6) -> 12 | C50: =RANK(C6,$B6:$V6) -> 4 | D50: =RANK(D6,$B6:$V6) -> 3 | E50: =RANK(E6,$B6:$V6) -> 2 | F50: =RANK(F6,$B6:$V6) -> 1 | G50: =RANK(G6,$B6:$V6) -> 18 | H50: =RANK(H6,$B6:$V6) -> 12 | I50: =RANK(I6,$B6:$V6) -> 19 | ... V50: =RANK(V6,$B6:$V6) -> 6
A51: =A7 -> FD | B51: =RANK(B7,$B7:$V7) -> 21 | C51: =RANK(C7,$B7:$V7) -> 17 | D51: =RANK(D7,$B7:$V7) -> 18 | E51: =RANK(E7,$B7:$V7) -> 20 | F51: =RANK(F7,$B7:$V7) -> 19 | G51: =RANK(G7,$B7:$V7) -> 6 | H51: =RANK(H7,$B7:$V7) -> 10 | I51: =RANK(I7,$B7:$V7) -> 9 | ... V51: =RANK(V7,$B7:$V7) -> 7
A52: =A8 -> HW | B52: =RANK(B8,$B8:$V8) -> 3 | C52: =RANK(C8,$B8:$V8) -> 4 | D52: =RANK(D8,$B8:$V8) -> 7 | E52: =RANK(E8,$B8:$V8) -> 6 | F52: =RANK(F8,$B8:$V8) -> 8 | G52: =RANK(G8,$B8:$V8) -> 20 | H52: =RANK(H8,$B8:$V8) -> 19 | I52: =RANK(I8,$B8:$V8) -> 21 | ... V52: =RANK(V8,$B8:$V8) -> 2
A53: =A9 -> HB | B53: =RANK(B9,$B9:$V9) -> 21 | C53: =RANK(C9,$B9:$V9) -> 19 | D53: =RANK(D9,$B9:$V9) -> 9 | E53: =RANK(E9,$B9:$V9) -> 17 | F53: =RANK(F9,$B9:$V9) -> 16 | G53: =RANK(G9,$B9:$V9) -> 17 | H53: =RANK(H9,$B9:$V9) -> 15 | I53: =RANK(I9,$B9:$V9) -> 6 | ... V53: =RANK(V9,$B9:$V9) -> 4
A54: =A10 -> JV | B54: =RANK(B10,$B10:$V10) -> 19 | C54: =RANK(C10,$B10:$V10) -> 21 | D54: =RANK(D10,$B10:$V10) -> 7 | E54: =RANK(E10,$B10:$V10) -> 14 | F54: =RANK(F10,$B10:$V10) -> 7 | G54: =RANK(G10,$B10:$V10) -> 18 | H54: =RANK(H10,$B10:$V10) -> 17 | I54: =RANK(I10,$B10:$V10) -> 19 | ... V54: =RANK(V10,$B10:$V10) -> 4
A55: =A11 -> PEMS | B55: =RANK(B11,$B11:$V11) -> 21 | C55: =RANK(C11,$B11:$V11) -> 17 | D55: =RANK(D11,$B11:$V11) -> 2 | E55: =RANK(E11,$B11:$V11) -> 1 | F55: =RANK(F11,$B11:$V11) -> 18 | G55: =RANK(G11,$B11:$V11) -> 18 | H55: =RANK(H11,$B11:$V11) -> 11 | I55: =RANK(I11,$B11:$V11) -> 20 | ... V55: =RANK(V11,$B11:$V11) -> 16
A56: =A12 -> SRS1 | B56: =RANK(B12,$B12:$V12) -> 20 | C56: =RANK(C12,$B12:$V12) -> 18 | D56: =RANK(D12,$B12:$V12) -> 15 | E56: =RANK(E12,$B12:$V12) -> 17 | F56: =RANK(F12,$B12:$V12) -> 1 | G56: =RANK(G12,$B12:$V12) -> 6 | H56: =RANK(H12,$B12:$V12) -> 6 | I56: =RANK(I12,$B12:$V12) -> 19 | ... V56: =RANK(V12,$B12:$V12) -> 9
A57: =A13 -> SRS2 | B57: =RANK(B13,$B13:$V13) -> 21 | C57: =RANK(C13,$B13:$V13) -> 18 | D57: =RANK(D13,$B13:$V13) -> 20 | E57: =RANK(E13,$B13:$V13) -> 13 | F57: =RANK(F13,$B13:$V13) -> 19 | G57: =RANK(G13,$B13:$V13) -> 17 | H57: =RANK(H13,$B13:$V13) -> 11 | I57: =RANK(I13,$B13:$V13) -> 15 | ... V57: =RANK(V13,$B13:$V13) -> 1
A58: =A14 -> SAD | B58: =RANK(B14,$B14:$V14) -> 19 | C58: =RANK(C14,$B14:$V14) -> 10 | D58: =RANK(D14,$B14:$V14) -> 11 | E58: =RANK(E14,$B14:$V14) -> 11 | F58: =RANK(F14,$B14:$V14) -> 13 | G58: =RANK(G14,$B14:$V14) -> 20 | H58: =RANK(H14,$B14:$V14) -> 17 | I58: =RANK(I14,$B14:$V14) -> 7 | ... V58: =RANK(V14,$B14:$V14) -> 1
A59: =A15 -> UW | B59: =RANK(B15,$B15:$V15) -> 9 | C59: =RANK(C15,$B15:$V15) -> 4 | D59: =RANK(D15,$B15:$V15) -> 4 | E59: =RANK(E15,$B15:$V15) -> 2 | F59: =RANK(F15,$B15:$V15) -> 4 | G59: =RANK(G15,$B15:$V15) -> 20 | H59: =RANK(H15,$B15:$V15) -> 13 | I59: =RANK(I15,$B15:$V15) -> 19 | ... V59: =RANK(V15,$B15:$V15) -> 7
A60: =A16 -> AWR | B60: =RANK(B16,$B16:$V16) -> 12 | C60: =RANK(C16,$B16:$V16) -> 1 | D60: =RANK(D16,$B16:$V16) -> 1 | E60: =RANK(E16,$B16:$V16) -> 1 | F60: =RANK(F16,$B16:$V16) -> 1 | G60: =RANK(G16,$B16:$V16) -> 20 | H60: =RANK(H16,$B16:$V16) -> 19 | I60: =RANK(I16,$B16:$V16) -> 8 | ... V60: =RANK(V16,$B16:$V16) -> 1
A61: =A17 -> AF | B61: =RANK(B17,$B17:$V17) -> 18 | C61: =RANK(C17,$B17:$V17) -> 20 | D61: =RANK(D17,$B17:$V17) -> 18 | E61: =RANK(E17,$B17:$V17) -> 17 | F61: =RANK(F17,$B17:$V17) -> 20 | G61: =RANK(G17,$B17:$V17) -> 14 | H61: =RANK(H17,$B17:$V17) -> 3 | I61: =RANK(I17,$B17:$V17) -> 13 | ... V61: =RANK(V17,$B17:$V17) -> 14
... A81: =A37 -> avg. acc | B81: =RANK(B37,$B37:$V37) -> 21 | C81: =RANK(C37,$B37:$V37) -> 18 | D81: =RANK(D37,$B37:$V37) -> 9 | E81: =RANK(E37,$B37:$V37) -> 6 | F81: =RANK(F37,$B37:$V37) -> 10 | G81: =RANK(G37,$B37:$V37) -> 20 | H81: =RANK(H37,$B37:$V37) -> 14 | I81: =RANK(I37,$B37:$V37) -> 19 | ... V81: =RANK(V37,$B37:$V37) -> 1
A82: =A38 -> avg. rank | B82: =RANK(B38,$B38:$V38,1) -> 20 | C82: =RANK(C38,$B38:$V38,1) -> 14 | D82: =RANK(D38,$B38:$V38,1) -> 9 | E82: =RANK(E38,$B38:$V38,1) -> 8 | F82: =RANK(F38,$B38:$V38,1) -> 11 | G82: =RANK(G38,$B38:$V38,1) -> 21 | H82: =RANK(H38,$B38:$V38,1) -> 15 | I82: =RANK(I38,$B38:$V38,1) -> 19 | ... V82: =RANK(V38,$B38:$V38,1) -> 1
A83: =A39 -> \# of top-1 | B83: =RANK(B39,$B39:$V39) -> 14 | C83: =RANK(C39,$B39:$V39) -> 8 | D83: =RANK(D39,$B39:$V39) -> 7 | E83: =RANK(E39,$B39:$V39) -> 2 | F83: =RANK(F39,$B39:$V39) -> 1 | G83: =RANK(G39,$B39:$V39) -> 20 | H83: =RANK(H39,$B39:$V39) -> 14 | I83: =RANK(I39,$B39:$V39) -> 14 | ... V83: =RANK(V39,$B39:$V39) -> 5
A84: =A40 -> \# of top-5 | B84: =RANK(B40,$B40:$V40) -> 19 | C84: =RANK(C40,$B40:$V40) -> 10 | D84: =RANK(D40,$B40:$V40) -> 4 | E84: =RANK(E40,$B40:$V40) -> 4 | F84: =RANK(F40,$B40:$V40) -> 6 | G84: =RANK(G40,$B40:$V40) -> 21 | H84: =RANK(H40,$B40:$V40) -> 13 | I84: =RANK(I40,$B40:$V40) -> 18 | ... V84: =RANK(V40,$B40:$V40) -> 1
A85: =A41 -> \# of top-10 | B85: =RANK(B41,$B41:$V41) -> 20 | C85: =RANK(C41,$B41:$V41) -> 13 | D85: =RANK(D41,$B41:$V41) -> 6 | E85: =RANK(E41,$B41:$V41) -> 8 | F85: =RANK(F41,$B41:$V41) -> 11 | G85: =RANK(G41,$B41:$V41) -> 20 | H85: =RANK(H41,$B41:$V41) -> 15 | I85: =RANK(I41,$B41:$V41) -> 18 | ... V85: =RANK(V41,$B41:$V41) -> 1

Sheet UEA30 (2)
B4: non-DL | G4: MLP-based | J4: CNN-based | L4: CNN-based | N4: Transformer-based | T4: shape-based | U4: Mamba-based
A5: Dataset | B5: DTW_D \citeyearpar{} | C5: ROCKET \citeyearpar{} | D5: HC2 \citeyearpar{} | E5: Hydra \citeyearpar{} | F5: MR+Hydra \citeyearpar{} | G5: Dlinear \citeyearpar{} | H5: LightTS \citeyearpar{} | I5: MTS-Mixer \citeyearpar{} | J5: TimesNet \citeyearpar{} | K5: ModernTCN \citeyearpar{} | L5: TSLANet \citeyearpar{} | M5: TimeMixer++ \citeyearpar{} | N5: FEDformer \citeyearpar{} | O5: ETSformer \citeyearpar{} | P5: Crossformer \citeyearpar{} | Q5: PatchTST \citeyearpar{} | R5: GPT4TS \citeyearpar{} | S5: iTransformer \citeyearpar{} | T5: InterpGN \citeyearpar{} | U5: TSCMamba \citeyearpar{} | V5: MambaSL \citeyearpar{}
A6: EC | B6: ='UEA30 (colored)'!B6 -> 32.319392 | C6: ='UEA30 (colored)'!C6 -> 44.486692 | D6: ='UEA30 (colored)'!D6 -> 52.851711 | E6: ='UEA30 (colored)'!E6 -> 54.372624 | F6: ='UEA30 (colored)'!F6 -> 60.076046 | G6: ='UEA30 (colored)'!G6 -> 31.178707 | H6: ='UEA30 (colored)'!H6 -> 32.319392 | I6: ='UEA30 (colored)'!I6 -> 30.798479 | ... V6: ='UEA30 (colored)'!V6 -> 42.585551
A7: FD | B7: ='UEA30 (colored)'!B7 -> 52.866061 | C7: ='UEA30 (colored)'!C7 -> 61.606129 | D7: ='UEA30 (colored)'!D7 -> 61.379115 | E7: ='UEA30 (colored)'!E7 -> 60.981839 | F7: ='UEA30 (colored)'!F7 -> 61.293984 | G7: ='UEA30 (colored)'!G7 -> 69.494892 | H7: ='UEA30 (colored)'!H7 -> 68.473326 | I7: ='UEA30 (colored)'!I7 -> 68.530079 | ... V7: ='UEA30 (colored)'!V7 -> 69.296254
A8: HW | B8: ='UEA30 (colored)'!B8 -> 60.705882 | C8: ='UEA30 (colored)'!C8 -> 59.294118 | D8: ='UEA30 (colored)'!D8 -> 56 | E8: ='UEA30 (colored)'!E8 -> 56.352941 | F8: ='UEA30 (colored)'!F8 -> 53.529412 | G8: ='UEA30 (colored)'!G8 -> 23.764706 | H8: ='UEA30 (colored)'!H8 -> 25.058824 | I8: ='UEA30 (colored)'!I8 -> 19.647059 | ... V8: ='UEA30 (colored)'!V8 -> 60.823529
A9: HB | B9: ='UEA30 (colored)'!B9 -> 71.707317 | C9: ='UEA30 (colored)'!C9 -> 75.609756 | D9: ='UEA30 (colored)'!D9 -> 78.536585 | E9: ='UEA30 (colored)'!E9 -> 76.585366 | F9: ='UEA30 (colored)'!F9 -> 77.073171 | G9: ='UEA30 (colored)'!G9 -> 76.585366 | H9: ='UEA30 (colored)'!H9 -> 77.560976 | I9: ='UEA30 (colored)'!I9 -> 79.02439 | ... V9: ='UEA30 (colored)'!V9 -> 80
A10: JV | B10: ='UEA30 (colored)'!B10 -> 95.945946 | C10: ='UEA30 (colored)'!C10 -> 83.783784 | D10: ='UEA30 (colored)'!D10 -> 98.378378 | E10: ='UEA30 (colored)'!E10 -> 97.837838 | F10: ='UEA30 (colored)'!F10 -> 98.378378 | G10: ='UEA30 (colored)'!G10 -> 96.486486 | H10: ='UEA30 (colored)'!H10 -> 96.756757 | I10: ='UEA30 (colored)'!I10 -> 95.945946 | ... V10: ='UEA30 (colored)'!V10 -> 98.648649
A11: PEMS | B11: ='UEA30 (colored)'!B11 -> 71.098266 | C11: ='UEA30 (colored)'!C11 -> 84.393064 | D11: ='UEA30 (colored)'!D11 -> 97.687861 | E11: ='UEA30 (colored)'!E11 -> 98.265896 | F11: ='UEA30 (colored)'!F11 -> 82.65896 | G11: ='UEA30 (colored)'!G11 -> 82.65896 | H11: ='UEA30 (colored)'!H11 -> 87.861272 | I11: ='UEA30 (colored)'!I11 -> 82.080925 | ... V11: ='UEA30 (colored)'!V11 -> 85.549133
A12: SRS1 | B12: ='UEA30 (colored)'!B12 -> 77.474403 | C12: ='UEA30 (colored)'!C12 -> 85.665529 | D12: ='UEA30 (colored)'!D12 -> 89.078498 | E12: ='UEA30 (colored)'!E12 -> 86.68942 | F12: ='UEA30 (colored)'!F12 -> 94.880546 | G12: ='UEA30 (colored)'!G12 -> 92.832765 | H12: ='UEA30 (colored)'!H12 -> 92.832765 | I12: ='UEA30 (colored)'!I12 -> 78.83959 | ... V12: ='UEA30 (colored)'!V12 -> 92.491468
A13: SRS2 | B13: ='UEA30 (colored)'!B13 -> 53.888889 | C13: ='UEA30 (colored)'!C13 -> 55.555556 | D13: ='UEA30 (colored)'!D13 -> 54.444444 | E13: ='UEA30 (colored)'!E13 -> 58.888889 | F13: ='UEA30 (colored)'!F13 -> 55 | G13: ='UEA30 (colored)'!G13 -> 57.222222 | H13: ='UEA30 (colored)'!H13 -> 59.444444 | I13: ='UEA30 (colored)'!I13 -> 58.333333 | ... V13: ='UEA30 (colored)'!V13 -> 65
A14: SAD | B14: ='UEA30 (colored)'!B14 -> 97.226012 | C14: ='UEA30 (colored)'!C14 -> 99.226921 | D14: ='UEA30 (colored)'!D14 -> 99.135971 | E14: ='UEA30 (colored)'!E14 -> 99.135971 | F14: ='UEA30 (colored)'!F14 -> 99.04502 | G14: ='UEA30 (colored)'!G14 -> 96.953161 | H14: ='UEA30 (colored)'!H14 -> 98.226467 | I14: ='UEA30 (colored)'!I14 -> 99.454297 | ... V14: ='UEA30 (colored)'!V14 -> 99.954525
A15: UW | B15: ='UEA30 (colored)'!B15 -> 90.3125 | C15: ='UEA30 (colored)'!C15 -> 94.0625 | D15: ='UEA30 (colored)'!D15 -> 94.0625 | E15: ='UEA30 (colored)'!E15 -> 94.375 | F15: ='UEA30 (colored)'!F15 -> 94.0625 | G15: ='UEA30 (colored)'!G15 -> 82.8125 | H15: ='UEA30 (colored)'!H15 -> 89.0625 | I15: ='UEA30 (colored)'!I15 -> 83.125 | ... V15: ='UEA30 (colored)'!V15 -> 93.4375
A16: AWR | B16: ='UEA30 (colored)'!B16 -> 98.666667 | C16: ='UEA30 (colored)'!C16 -> 99.333333 | D16: ='UEA30 (colored)'!D16 -> 99.333333 | E16: ='UEA30 (colored)'!E16 -> 99.333333 | F16: ='UEA30 (colored)'!F16 -> 99.333333 | G16: ='UEA30 (colored)'!G16 -> 97.666667 | H16: ='UEA30 (colored)'!H16 -> 98.333333 | I16: ='UEA30 (colored)'!I16 -> 99 | ... V16: ='UEA30 (colored)'!V16 -> 99.333333
A17: AF | B17: ='UEA30 (colored)'!B17 -> 20 | C17: ='UEA30 (colored)'!C17 -> 6.6666667 | D17: ='UEA30 (colored)'!D17 -> 20 | E17: ='UEA30 (colored)'!E17 -> 26.666667 | F17: ='UEA30 (colored)'!F17 -> 6.6666667 | G17: ='UEA30 (colored)'!G17 -> 53.333333 | H17: ='UEA30 (colored)'!H17 -> 73.333333 | I17: ='UEA30 (colored)'!I17 -> 60 | ... V17: ='UEA30 (colored)'!V17 -> 53.333333
... A43: \# of lose/draw | B43: ='UEA30 (colored)'!B43 -> 2 | C43: ='UEA30 (colored)'!C43 -> 9 | D43: ='UEA30 (colored)'!D43 -> 14 | E43: ='UEA30 (colored)'!E43 -> 13 | F43: ='UEA30 (colored)'!F43 -> 11 | G43: ='UEA30 (colored)'!G43 -> 3 | H43: ='UEA30 (colored)'!H43 -> 7 | I43: ='UEA30 (colored)'!I43 -> 4 | ... V43: ='UEA30 (colored)'!V43 -> 0
A44: Wilcoxon test | B44: ='UEA30 (colored)'!B44 -> 3.6148028e-06 | C44: ='UEA30 (colored)'!C44 -> 0.0008239998 | D44: ='UEA30 (colored)'!D44 -> 0.05621403 | E44: ='UEA30 (colored)'!E44 -> 0.033932669 | F44: ='UEA30 (colored)'!F44 -> 0.015259624 | G44: ='UEA30 (colored)'!G44 -> 1.7574815e-06 | H44: ='UEA30 (colored)'!H44 -> 0.00010291886 | I44: ='UEA30 (colored)'!I44 -> 4.9888494e-06 | ... U44: ='UEA30 (colored)'!U44 -> 0.041326512
A50: =A6 -> EC | B50: =RANK(B6,$B6:$V6) -> 12 | C50: =RANK(C6,$B6:$V6) -> 4 | D50: =RANK(D6,$B6:$V6) -> 3 | E50: =RANK(E6,$B6:$V6) -> 2 | F50: =RANK(F6,$B6:$V6) -> 1 | G50: =RANK(G6,$B6:$V6) -> 18 | H50: =RANK(H6,$B6:$V6) -> 12 | I50: =RANK(I6,$B6:$V6) -> 19 | ... V50: =RANK(V6,$B6:$V6) -> 6
A51: =A7 -> FD | B51: =RANK(B7,$B7:$V7) -> 21 | C51: =RANK(C7,$B7:$V7) -> 17 | D51: =RANK(D7,$B7:$V7) -> 18 | E51: =RANK(E7,$B7:$V7) -> 20 | F51: =RANK(F7,$B7:$V7) -> 19 | G51: =RANK(G7,$B7:$V7) -> 6 | H51: =RANK(H7,$B7:$V7) -> 10 | I51: =RANK(I7,$B7:$V7) -> 9 | ... V51: =RANK(V7,$B7:$V7) -> 7
A52: =A8 -> HW | B52: =RANK(B8,$B8:$V8) -> 3 | C52: =RANK(C8,$B8:$V8) -> 4 | D52: =RANK(D8,$B8:$V8) -> 7 | E52: =RANK(E8,$B8:$V8) -> 6 | F52: =RANK(F8,$B8:$V8) -> 8 | G52: =RANK(G8,$B8:$V8) -> 20 | H52: =RANK(H8,$B8:$V8) -> 19 | I52: =RANK(I8,$B8:$V8) -> 21 | ... V52: =RANK(V8,$B8:$V8) -> 2
A53: =A9 -> HB | B53: =RANK(B9,$B9:$V9) -> 21 | C53: =RANK(C9,$B9:$V9) -> 19 | D53: =RANK(D9,$B9:$V9) -> 9 | E53: =RANK(E9,$B9:$V9) -> 17 | F53: =RANK(F9,$B9:$V9) -> 16 | G53: =RANK(G9,$B9:$V9) -> 17 | H53: =RANK(H9,$B9:$V9) -> 15 | I53: =RANK(I9,$B9:$V9) -> 6 | ... V53: =RANK(V9,$B9:$V9) -> 4
A54: =A10 -> JV | B54: =RANK(B10,$B10:$V10) -> 19 | C54: =RANK(C10,$B10:$V10) -> 21 | D54: =RANK(D10,$B10:$V10) -> 7 | E54: =RANK(E10,$B10:$V10) -> 14 | F54: =RANK(F10,$B10:$V10) -> 7 | G54: =RANK(G10,$B10:$V10) -> 18 | H54: =RANK(H10,$B10:$V10) -> 17 | I54: =RANK(I10,$B10:$V10) -> 19 | ... V54: =RANK(V10,$B10:$V10) -> 4
A55: =A11 -> PEMS | B55: =RANK(B11,$B11:$V11) -> 21 | C55: =RANK(C11,$B11:$V11) -> 17 | D55: =RANK(D11,$B11:$V11) -> 2 | E55: =RANK(E11,$B11:$V11) -> 1 | F55: =RANK(F11,$B11:$V11) -> 18 | G55: =RANK(G11,$B11:$V11) -> 18 | H55: =RANK(H11,$B11:$V11) -> 11 | I55: =RANK(I11,$B11:$V11) -> 20 | ... V55: =RANK(V11,$B11:$V11) -> 16
A56: =A12 -> SRS1 | B56: =RANK(B12,$B12:$V12) -> 20 | C56: =RANK(C12,$B12:$V12) -> 18 | D56: =RANK(D12,$B12:$V12) -> 15 | E56: =RANK(E12,$B12:$V12) -> 17 | F56: =RANK(F12,$B12:$V12) -> 1 | G56: =RANK(G12,$B12:$V12) -> 6 | H56: =RANK(H12,$B12:$V12) -> 6 | I56: =RANK(I12,$B12:$V12) -> 19 | ... V56: =RANK(V12,$B12:$V12) -> 9
A57: =A13 -> SRS2 | B57: =RANK(B13,$B13:$V13) -> 21 | C57: =RANK(C13,$B13:$V13) -> 18 | D57: =RANK(D13,$B13:$V13) -> 20 | E57: =RANK(E13,$B13:$V13) -> 13 | F57: =RANK(F13,$B13:$V13) -> 19 | G57: =RANK(G13,$B13:$V13) -> 17 | H57: =RANK(H13,$B13:$V13) -> 11 | I57: =RANK(I13,$B13:$V13) -> 15 | ... V57: =RANK(V13,$B13:$V13) -> 1
A58: =A14 -> SAD | B58: =RANK(B14,$B14:$V14) -> 19 | C58: =RANK(C14,$B14:$V14) -> 10 | D58: =RANK(D14,$B14:$V14) -> 11 | E58: =RANK(E14,$B14:$V14) -> 11 | F58: =RANK(F14,$B14:$V14) -> 13 | G58: =RANK(G14,$B14:$V14) -> 20 | H58: =RANK(H14,$B14:$V14) -> 17 | I58: =RANK(I14,$B14:$V14) -> 7 | ... V58: =RANK(V14,$B14:$V14) -> 1
A59: =A15 -> UW | B59: =RANK(B15,$B15:$V15) -> 9 | C59: =RANK(C15,$B15:$V15) -> 4 | D59: =RANK(D15,$B15:$V15) -> 4 | E59: =RANK(E15,$B15:$V15) -> 2 | F59: =RANK(F15,$B15:$V15) -> 4 | G59: =RANK(G15,$B15:$V15) -> 20 | H59: =RANK(H15,$B15:$V15) -> 13 | I59: =RANK(I15,$B15:$V15) -> 19 | ... V59: =RANK(V15,$B15:$V15) -> 7
A60: =A16 -> AWR | B60: =RANK(B16,$B16:$V16) -> 12 | C60: =RANK(C16,$B16:$V16) -> 1 | D60: =RANK(D16,$B16:$V16) -> 1 | E60: =RANK(E16,$B16:$V16) -> 1 | F60: =RANK(F16,$B16:$V16) -> 1 | G60: =RANK(G16,$B16:$V16) -> 20 | H60: =RANK(H16,$B16:$V16) -> 19 | I60: =RANK(I16,$B16:$V16) -> 8 | ... V60: =RANK(V16,$B16:$V16) -> 1
A61: =A17 -> AF | B61: =RANK(B17,$B17:$V17) -> 18 | C61: =RANK(C17,$B17:$V17) -> 20 | D61: =RANK(D17,$B17:$V17) -> 18 | E61: =RANK(E17,$B17:$V17) -> 17 | F61: =RANK(F17,$B17:$V17) -> 20 | G61: =RANK(G17,$B17:$V17) -> 14 | H61: =RANK(H17,$B17:$V17) -> 3 | I61: =RANK(I17,$B17:$V17) -> 13 | ... V61: =RANK(V17,$B17:$V17) -> 14
... A81: =A37 -> avg. acc | B81: =RANK(B37,$B37:$V37) -> 21 | C81: =RANK(C37,$B37:$V37) -> 18 | D81: =RANK(D37,$B37:$V37) -> 9 | E81: =RANK(E37,$B37:$V37) -> 6 | F81: =RANK(F37,$B37:$V37) -> 10 | G81: =RANK(G37,$B37:$V37) -> 20 | H81: =RANK(H37,$B37:$V37) -> 14 | I81: =RANK(I37,$B37:$V37) -> 19 | ... V81: =RANK(V37,$B37:$V37) -> 1
A82: =A38 -> avg. rank | B82: =RANK(B38,$B38:$V38,1) -> 20 | C82: =RANK(C38,$B38:$V38,1) -> 14 | D82: =RANK(D38,$B38:$V38,1) -> 9 | E82: =RANK(E38,$B38:$V38,1) -> 8 | F82: =RANK(F38,$B38:$V38,1) -> 11 | G82: =RANK(G38,$B38:$V38,1) -> 21 | H82: =RANK(H38,$B38:$V38,1) -> 15 | I82: =RANK(I38,$B38:$V38,1) -> 19 | ... V82: =RANK(V38,$B38:$V38,1) -> 1
A83: =A39 -> \# of top-1 | B83: =RANK(B39,$B39:$V39) -> 14 | C83: =RANK(C39,$B39:$V39) -> 8 | D83: =RANK(D39,$B39:$V39) -> 7 | E83: =RANK(E39,$B39:$V39) -> 2 | F83: =RANK(F39,$B39:$V39) -> 1 | G83: =RANK(G39,$B39:$V39) -> 20 | H83: =RANK(H39,$B39:$V39) -> 14 | I83: =RANK(I39,$B39:$V39) -> 14 | ... V83: =RANK(V39,$B39:$V39) -> 5
A84: =A40 -> \# of top-5 | B84: =RANK(B40,$B40:$V40) -> 19 | C84: =RANK(C40,$B40:$V40) -> 10 | D84: =RANK(D40,$B40:$V40) -> 4 | E84: =RANK(E40,$B40:$V40) -> 4 | F84: =RANK(F40,$B40:$V40) -> 6 | G84: =RANK(G40,$B40:$V40) -> 21 | H84: =RANK(H40,$B40:$V40) -> 13 | I84: =RANK(I40,$B40:$V40) -> 18 | ... V84: =RANK(V40,$B40:$V40) -> 1
A85: =A41 -> \# of top-10 | B85: =RANK(B41,$B41:$V41) -> 20 | C85: =RANK(C41,$B41:$V41) -> 13 | D85: =RANK(D41,$B41:$V41) -> 6 | E85: =RANK(E41,$B41:$V41) -> 8 | F85: =RANK(F41,$B41:$V41) -> 11 | G85: =RANK(G41,$B41:$V41) -> 20 | H85: =RANK(H41,$B41:$V41) -> 15 | I85: =RANK(I41,$B41:$V41) -> 18 | ... V85: =RANK(V41,$B41:$V41) -> 1

Sheet UEA description
B3: Dataset | C3: Code | E3: Train Size | F3: Test Size | G3: Length ($L$) | H3: Variables ($d_\mathrm{x}$) | I3: Classes ($d_\mathrm{y}$)
A4: 01 | B4: EthanolConcentration | C4: \texttt{ EC } | D4: EC | E4: 261 | F4: 263 | G4: 1751 | H4: 3 | I4: 4 | L4: \texttt{ | M4: EC | N4: }
A5: 02 | B5: FaceDetection | C5: \texttt{ FD } | D5: FD | E5: 5890 | F5: 3524 | G5: 62 | H5: 144 | I5: 2 | L5: \texttt{ | M5: FD | N5: }
A6: 03 | B6: Handwriting | C6: \texttt{ HW } | D6: HW | E6: 150 | F6: 850 | G6: 152 | H6: 3 | I6: 26 | L6: \texttt{ | M6: HW | N6: }
A7: 04 | B7: Heartbeat | C7: \texttt{ HB } | D7: HB | E7: 204 | F7: 205 | G7: 405 | H7: 61 | I7: 2 | L7: \texttt{ | M7: HB | N7: }
A8: 05 | B8: JapaneseVowels | C8: \texttt{ JV } | D8: JV | E8: 270 | F8: 370 | G8: 7--29 | H8: 12 | I8: 9 | L8: \texttt{ | M8: JV | N8: }
A9: 06 | B9: PEMS-SF | C9: \texttt{ PEMS } | D9: PEMS | E9: 267 | F9: 173 | G9: 144 | H9: 963 | I9: 7 | L9: \texttt{ | M9: PEMS | N9: }
A10: 07 | B10: SelfRegulationSCP1 | C10: \texttt{ SRS1 } | D10: SRS1 | E10: 268 | F10: 293 | G10: 896 | H10: 6 | I10: 2 | L10: \texttt{ | M10: SRS1 | N10: }
A11: 08 | B11: SelfRegulationSCP2 | C11: \texttt{ SRS2 } | D11: SRS2 | E11: 200 | F11: 180 | G11: 1152 | H11: 7 | I11: 2 | L11: \texttt{ | M11: SRS2 | N11: }
A12: 09 | B12: SpokenArabicDigits | C12: \texttt{ SAD } | D12: SAD | E12: 6599 | F12: 2199 | G12: 4--93 | H12: 13 | I12: 10 | L12: \texttt{ | M12: SAD | N12: }
A13: 10 | B13: UWaveGestureLibrary | C13: \texttt{ UW } | D13: UW | E13: 120 | F13: 320 | G13: 315 | H13: 3 | I13: 8 | L13: \texttt{ | M13: UW | N13: }
A14: 11 | B14: ArticularyWordRecognition | C14: \texttt{ AWR } | D14: AWR | E14: 275 | F14: 300 | G14: 144 | H14: 9 | I14: 25 | L14: \texttt{ | M14: AWR | N14: }
A15: 12 | B15: AtrialFibrillation | C15: \texttt{ AF } | D15: AF | E15: 15 | F15: 15 | G15: 640 | H15: 2 | I15: 3 | L15: \texttt{ | M15: AF | N15: }
A16: 13 | B16: BasicMotions | C16: \texttt{ BM } | D16: BM | E16: 40 | F16: 40 | G16: 100 | H16: 6 | I16: 4 | L16: \texttt{ | M16: BM | N16: }
A17: 14 | B17: CharacterTrajectories | C17: \texttt{ CT } | D17: CT | E17: 1422 | F17: 1436 | G17: 60--182 | H17: 3 | I17: 20 | L17: \texttt{ | M17: CT | N17: }
A18: 15 | B18: Cricket | C18: \texttt{ CR } | D18: CR | E18: 108 | F18: 72 | G18: 1197 | H18: 6 | I18: 12 | L18: \texttt{ | M18: CR | N18: }
A19: 16 | B19: DuckDuckGeese | C19: \texttt{ DDG } | D19: DDG | E19: 50 | F19: 50 | G19: 270 | H19: 1345 | I19: 5 | L19: \texttt{ | M19: DDG | N19: }
A20: 17 | B20: EigenWorms | C20: \texttt{ EW } | D20: EW | E20: 128 | F20: 131 | G20: 17984 | H20: 6 | I20: 5 | L20: \texttt{ | M20: EW | N20: }
A21: 18 | B21: Epilepsy | C21: \texttt{ EP } | D21: EP | E21: 137 | F21: 138 | G21: 206 | H21: 3 | I21: 4 | L21: \texttt{ | M21: EP | N21: }
A22: 19 | B22: ERing | C22: \texttt{ ER } | D22: ER | E22: 30 | F22: 270 | G22: 65 | H22: 4 | I22: 6 | L22: \texttt{ | M22: ER | N22: }
A23: 20 | B23: FingerMovements | C23: \texttt{ FM } | D23: FM | E23: 316 | F23: 100 | G23: 50 | H23: 28 | I23: 2 | L23: \texttt{ | M23: FM | N23: }
A24: 21 | B24: HandMovementDirection | C24: \texttt{ HMD } | D24: HMD | E24: 160 | F24: 74 | G24: 400 | H24: 10 | I24: 4 | L24: \texttt{ | M24: HMD | N24: }
A25: 22 | B25: InsectWingbeat | C25: \texttt{ IW } | D25: IW | E25: 25000 | F25: 25000 | G25: 2--22 | H25: 200 | I25: 10 | L25: \texttt{ | M25: IW | N25: }
A26: 23 | B26: Libras | C26: \texttt{ LIB } | D26: LIB | E26: 180 | F26: 180 | G26: 45 | H26: 2 | I26: 15 | L26: \texttt{ | M26: LIB | N26: }
A27: 24 | B27: LSST | C27: \texttt{ LSST } | D27: LSST | E27: 2459 | F27: 2466 | G27: 36 | H27: 6 | I27: 14 | L27: \texttt{ | M27: LSST | N27: }
A28: 25 | B28: MotorImagery | C28: \texttt{ MI } | D28: MI | E28: 278 | F28: 100 | G28: 3000 | H28: 64 | I28: 2 | L28: \texttt{ | M28: MI | N28: }
A29: 26 | B29: NATOPS | C29: \texttt{ NATO } | D29: NATO | E29: 180 | F29: 180 | G29: 51 | H29: 24 | I29: 6 | L29: \texttt{ | M29: NATO | N29: }
A30: 27 | B30: PenDigits | C30: \texttt{ PD } | D30: PD | E30: 7494 | F30: 3498 | G30: 8 | H30: 2 | I30: 10 | L30: \texttt{ | M30: PD | N30: }
A31: 28 | B31: PhonemeSpectra | C31: \texttt{ PS } | D31: PS | E31: 3315 | F31: 3353 | G31: 217 | H31: 11 | I31: 39 | L31: \texttt{ | M31: PS | N31: }
A32: 29 | B32: RacketSports | C32: \texttt{ RS } | D32: RS | E32: 151 | F32: 152 | G32: 30 | H32: 6 | I32: 4 | L32: \texttt{ | M32: RS | N32: }
A33: 30 | B33: StandWalkJump | C33: \texttt{ SWJ } | D33: SWJ | E33: 12 | F33: 15 | G33: 2500 | H33: 4 | I33: 3 | L33: \texttt{ | M33: SWJ | N33: }
